[2025-04-21T17:30:08.665+0000] {local_task_job_runner.py:123} INFO - ::group::Pre task execution logs
[2025-04-21T17:30:08.715+0000] {taskinstance.py:2614} INFO - Dependencies all met for dep_context=non-requeueable deps ti=<TaskInstance: lstm_stock_prediction_refactored.generate_predictions manual__2025-04-21T17:25:59.922791+00:00 [queued]>
[2025-04-21T17:30:08.736+0000] {taskinstance.py:2614} INFO - Dependencies all met for dep_context=requeueable deps ti=<TaskInstance: lstm_stock_prediction_refactored.generate_predictions manual__2025-04-21T17:25:59.922791+00:00 [queued]>
[2025-04-21T17:30:08.739+0000] {taskinstance.py:2867} INFO - Starting attempt 2 of 2
[2025-04-21T17:30:08.768+0000] {taskinstance.py:2890} INFO - Executing <Task(BashOperator): generate_predictions> on 2025-04-21 17:25:59.922791+00:00
[2025-04-21T17:30:08.786+0000] {standard_task_runner.py:72} INFO - Started process 823 to run task
[2025-04-21T17:30:08.791+0000] {standard_task_runner.py:104} INFO - Running: ['***', 'tasks', 'run', 'lstm_stock_prediction_refactored', 'generate_predictions', 'manual__2025-04-21T17:25:59.922791+00:00', '--job-id', '12', '--raw', '--subdir', 'DAGS_FOLDER/lstm_refactored_dag.py', '--cfg-path', '/tmp/tmphctex4ln']
[2025-04-21T17:30:08.794+0000] {standard_task_runner.py:105} INFO - Job 12: Subtask generate_predictions
[2025-04-21T17:30:08.857+0000] {task_command.py:467} INFO - Running <TaskInstance: lstm_stock_prediction_refactored.generate_predictions manual__2025-04-21T17:25:59.922791+00:00 [running]> on host a528bcf7a8c9
[2025-04-21T17:30:08.961+0000] {taskinstance.py:3134} INFO - Exporting env vars: AIRFLOW_CTX_DAG_OWNER='***_team' AIRFLOW_CTX_DAG_ID='lstm_stock_prediction_refactored' AIRFLOW_CTX_TASK_ID='generate_predictions' AIRFLOW_CTX_EXECUTION_DATE='2025-04-21T17:25:59.922791+00:00' AIRFLOW_CTX_TRY_NUMBER='2' AIRFLOW_CTX_DAG_RUN_ID='manual__2025-04-21T17:25:59.922791+00:00'
[2025-04-21T17:30:08.963+0000] {taskinstance.py:732} INFO - ::endgroup::
[2025-04-21T17:30:08.980+0000] {subprocess.py:78} INFO - Tmp dir root location: /tmp
[2025-04-21T17:30:08.982+0000] {subprocess.py:88} INFO - Running command: ['/usr/bin/bash', '-c', 'python /opt/***/src/models/predict_model.py --config /opt/***/config/params.yaml']
[2025-04-21T17:30:08.995+0000] {subprocess.py:99} INFO - Output:
[2025-04-21T17:30:17.950+0000] {subprocess.py:106} INFO - Traceback (most recent call last):
[2025-04-21T17:30:17.951+0000] {subprocess.py:106} INFO -   File "/opt/***/src/models/predict_model.py", line 132, in <module>
[2025-04-21T17:30:17.952+0000] {subprocess.py:106} INFO -     if _name_ == '_main_':
[2025-04-21T17:30:17.953+0000] {subprocess.py:106} INFO -        ^^^^^^
[2025-04-21T17:30:17.954+0000] {subprocess.py:106} INFO - NameError: name '_name_' is not defined. Did you mean: '__name__'?
[2025-04-21T17:30:19.394+0000] {subprocess.py:110} INFO - Command exited with return code 1
[2025-04-21T17:30:19.412+0000] {taskinstance.py:3313} ERROR - Task failed with exception
Traceback (most recent call last):
  File "/home/airflow/.local/lib/python3.11/site-packages/airflow/models/taskinstance.py", line 768, in _execute_task
    result = _execute_callable(context=context, **execute_callable_kwargs)
             ^^^^^^^^^^^^^^^^^^^^^^^^^^^^^^^^^^^^^^^^^^^^^^^^^^^^^^^^^^^^^
  File "/home/airflow/.local/lib/python3.11/site-packages/airflow/models/taskinstance.py", line 734, in _execute_callable
    return ExecutionCallableRunner(
           ^^^^^^^^^^^^^^^^^^^^^^^^
  File "/home/airflow/.local/lib/python3.11/site-packages/airflow/utils/operator_helpers.py", line 252, in run
    return self.func(*args, **kwargs)
           ^^^^^^^^^^^^^^^^^^^^^^^^^^
  File "/home/airflow/.local/lib/python3.11/site-packages/airflow/models/baseoperator.py", line 424, in wrapper
    return func(self, *args, **kwargs)
           ^^^^^^^^^^^^^^^^^^^^^^^^^^^
  File "/home/airflow/.local/lib/python3.11/site-packages/airflow/operators/bash.py", line 276, in execute
    raise AirflowException(
airflow.exceptions.AirflowException: Bash command failed. The command returned a non-zero exit code 1.
[2025-04-21T17:30:19.424+0000] {taskinstance.py:1226} INFO - Marking task as FAILED. dag_id=lstm_stock_prediction_refactored, task_id=generate_predictions, run_id=manual__2025-04-21T17:25:59.922791+00:00, execution_date=20250421T172559, start_date=20250421T173008, end_date=20250421T173019
[2025-04-21T17:30:19.463+0000] {taskinstance.py:341} INFO - ::group::Post task execution logs
[2025-04-21T17:30:19.464+0000] {standard_task_runner.py:124} ERROR - Failed to execute job 12 for task generate_predictions (Bash command failed. The command returned a non-zero exit code 1.; 823)
Traceback (most recent call last):
  File "/home/airflow/.local/lib/python3.11/site-packages/airflow/task/task_runner/standard_task_runner.py", line 117, in _start_by_fork
    ret = args.func(args, dag=self.dag)
          ^^^^^^^^^^^^^^^^^^^^^^^^^^^^^
  File "/home/airflow/.local/lib/python3.11/site-packages/airflow/cli/cli_config.py", line 49, in command
    return func(*args, **kwargs)
           ^^^^^^^^^^^^^^^^^^^^^
  File "/home/airflow/.local/lib/python3.11/site-packages/airflow/utils/cli.py", line 116, in wrapper
    return f(*args, **kwargs)
           ^^^^^^^^^^^^^^^^^^
  File "/home/airflow/.local/lib/python3.11/site-packages/airflow/cli/commands/task_command.py", line 483, in task_run
    task_return_code = _run_task_by_selected_method(args, _dag, ti)
                       ^^^^^^^^^^^^^^^^^^^^^^^^^^^^^^^^^^^^^^^^^^^^
  File "/home/airflow/.local/lib/python3.11/site-packages/airflow/cli/commands/task_command.py", line 256, in _run_task_by_selected_method
    return _run_raw_task(args, ti)
           ^^^^^^^^^^^^^^^^^^^^^^^
  File "/home/airflow/.local/lib/python3.11/site-packages/airflow/cli/commands/task_command.py", line 341, in _run_raw_task
    return ti._run_raw_task(
           ^^^^^^^^^^^^^^^^^
  File "/home/airflow/.local/lib/python3.11/site-packages/airflow/utils/session.py", line 97, in wrapper
    return func(*args, session=session, **kwargs)
           ^^^^^^^^^^^^^^^^^^^^^^^^^^^^^^^^^^^^^^
  File "/home/airflow/.local/lib/python3.11/site-packages/airflow/models/taskinstance.py", line 3006, in _run_raw_task
    return _run_raw_task(
           ^^^^^^^^^^^^^^
  File "/home/airflow/.local/lib/python3.11/site-packages/airflow/models/taskinstance.py", line 274, in _run_raw_task
    TaskInstance._execute_task_with_callbacks(
  File "/home/airflow/.local/lib/python3.11/site-packages/airflow/models/taskinstance.py", line 3161, in _execute_task_with_callbacks
    result = self._execute_task(context, task_orig)
             ^^^^^^^^^^^^^^^^^^^^^^^^^^^^^^^^^^^^^^
  File "/home/airflow/.local/lib/python3.11/site-packages/airflow/models/taskinstance.py", line 3185, in _execute_task
    return _execute_task(self, context, task_orig)
           ^^^^^^^^^^^^^^^^^^^^^^^^^^^^^^^^^^^^^^^
  File "/home/airflow/.local/lib/python3.11/site-packages/airflow/models/taskinstance.py", line 768, in _execute_task
    result = _execute_callable(context=context, **execute_callable_kwargs)
             ^^^^^^^^^^^^^^^^^^^^^^^^^^^^^^^^^^^^^^^^^^^^^^^^^^^^^^^^^^^^^
  File "/home/airflow/.local/lib/python3.11/site-packages/airflow/models/taskinstance.py", line 734, in _execute_callable
    return ExecutionCallableRunner(
           ^^^^^^^^^^^^^^^^^^^^^^^^
  File "/home/airflow/.local/lib/python3.11/site-packages/airflow/utils/operator_helpers.py", line 252, in run
    return self.func(*args, **kwargs)
           ^^^^^^^^^^^^^^^^^^^^^^^^^^
  File "/home/airflow/.local/lib/python3.11/site-packages/airflow/models/baseoperator.py", line 424, in wrapper
    return func(self, *args, **kwargs)
           ^^^^^^^^^^^^^^^^^^^^^^^^^^^
  File "/home/airflow/.local/lib/python3.11/site-packages/airflow/operators/bash.py", line 276, in execute
    raise AirflowException(
airflow.exceptions.AirflowException: Bash command failed. The command returned a non-zero exit code 1.
[2025-04-21T17:30:19.489+0000] {local_task_job_runner.py:266} INFO - Task exited with return code 1
[2025-04-21T17:30:19.506+0000] {taskinstance.py:3901} INFO - 0 downstream tasks scheduled from follow-on schedule check
[2025-04-21T17:30:19.508+0000] {local_task_job_runner.py:245} INFO - ::endgroup::
