[2025-04-11T08:32:09.520+0000] {local_task_job_runner.py:123} INFO - ::group::Pre task execution logs
[2025-04-11T08:32:09.539+0000] {taskinstance.py:2614} INFO - Dependencies all met for dep_context=non-requeueable deps ti=<TaskInstance: lstm_stock_prediction_refactored.train_final_model manual__2025-04-11T07:34:50.523738+00:00 [queued]>
[2025-04-11T08:32:09.551+0000] {taskinstance.py:2614} INFO - Dependencies all met for dep_context=requeueable deps ti=<TaskInstance: lstm_stock_prediction_refactored.train_final_model manual__2025-04-11T07:34:50.523738+00:00 [queued]>
[2025-04-11T08:32:09.553+0000] {taskinstance.py:2867} INFO - Starting attempt 7 of 8
[2025-04-11T08:32:09.568+0000] {taskinstance.py:2890} INFO - Executing <Task(BashOperator): train_final_model> on 2025-04-11 07:34:50.523738+00:00
[2025-04-11T08:32:09.573+0000] {standard_task_runner.py:72} INFO - Started process 222 to run task
[2025-04-11T08:32:09.576+0000] {standard_task_runner.py:104} INFO - Running: ['***', 'tasks', 'run', 'lstm_stock_prediction_refactored', 'train_final_model', 'manual__2025-04-11T07:34:50.523738+00:00', '--job-id', '33', '--raw', '--subdir', 'DAGS_FOLDER/lstm_refactored_dag.py', '--cfg-path', '/tmp/tmpkw_k170f']
[2025-04-11T08:32:09.579+0000] {standard_task_runner.py:105} INFO - Job 33: Subtask train_final_model
[2025-04-11T08:32:09.621+0000] {task_command.py:467} INFO - Running <TaskInstance: lstm_stock_prediction_refactored.train_final_model manual__2025-04-11T07:34:50.523738+00:00 [running]> on host 9a504a0ea752
[2025-04-11T08:32:09.688+0000] {taskinstance.py:3134} INFO - Exporting env vars: AIRFLOW_CTX_DAG_OWNER='***_team' AIRFLOW_CTX_DAG_ID='lstm_stock_prediction_refactored' AIRFLOW_CTX_TASK_ID='train_final_model' AIRFLOW_CTX_EXECUTION_DATE='2025-04-11T07:34:50.523738+00:00' AIRFLOW_CTX_TRY_NUMBER='7' AIRFLOW_CTX_DAG_RUN_ID='manual__2025-04-11T07:34:50.523738+00:00'
[2025-04-11T08:32:09.689+0000] {taskinstance.py:732} INFO - ::endgroup::
[2025-04-11T08:32:09.705+0000] {subprocess.py:78} INFO - Tmp dir root location: /tmp
[2025-04-11T08:32:09.706+0000] {subprocess.py:88} INFO - Running command: ['/usr/bin/bash', '-c', 'python /opt/***/src/models/train_model.py --config /opt/***/config/params.yaml']
[2025-04-11T08:32:09.714+0000] {subprocess.py:99} INFO - Output:
[2025-04-11T08:36:21.290+0000] {subprocess.py:106} INFO - Using device: cpu
[2025-04-11T08:36:21.291+0000] {subprocess.py:106} INFO - --- Loading Scaled Data from /opt/***/data/features/split_scaled_data.npz ---
[2025-04-11T08:36:21.292+0000] {subprocess.py:106} INFO - --- Finished Loading Scaled Data ---
[2025-04-11T08:36:21.292+0000] {subprocess.py:106} INFO - --- Loading Scalers from /opt/***/data/processed/scalers.pkl ---
[2025-04-11T08:36:21.293+0000] {subprocess.py:106} INFO - --- Finished Loading Scalers ---
[2025-04-11T08:36:21.293+0000] {subprocess.py:106} INFO - --- Loading Tickers from /opt/***/data/processed/all_processed_data.npz ---
[2025-04-11T08:36:21.294+0000] {subprocess.py:106} INFO - Tickers: ['AAPL', 'MA', 'CSCO', 'MSFT', 'AMZN', 'GOOG', 'IBM']
[2025-04-11T08:36:21.295+0000] {subprocess.py:106} INFO - --- Finished Loading Tickers ---
[2025-04-11T08:36:21.295+0000] {subprocess.py:106} INFO - --- Loading Best Hyperparameters from /opt/***/config/best_params.json ---
[2025-04-11T08:36:21.295+0000] {subprocess.py:106} INFO - Best parameters loaded: {'batch_size': 80, 'hidden_size': 64, 'num_layers': 2, 'dropout_rate': 0.4, 'learning_rate': 0.00010587273351810358, 'model_type': 'lstm_cross_attention'}
[2025-04-11T08:36:21.296+0000] {subprocess.py:106} INFO - --- Finished Loading Best Hyperparameters ---
[2025-04-11T08:36:21.298+0000] {subprocess.py:106} INFO - --- Setting MLflow Experiment: Stock_Price_Prediction_LSTM_Refactored ---
[2025-04-11T08:36:21.299+0000] {subprocess.py:106} INFO - Using MLflow Tracking URI: http://localhost:5001/
[2025-04-11T08:36:21.299+0000] {subprocess.py:106} INFO - Traceback (most recent call last):
[2025-04-11T08:36:21.299+0000] {subprocess.py:106} INFO -   File "/home/***/.local/lib/python3.11/site-packages/urllib3/connection.py", line 198, in _new_conn
[2025-04-11T08:36:21.300+0000] {subprocess.py:106} INFO -     sock = connection.create_connection(
[2025-04-11T08:36:21.300+0000] {subprocess.py:106} INFO -            ^^^^^^^^^^^^^^^^^^^^^^^^^^^^^
[2025-04-11T08:36:21.301+0000] {subprocess.py:106} INFO -   File "/home/***/.local/lib/python3.11/site-packages/urllib3/util/connection.py", line 85, in create_connection
[2025-04-11T08:36:21.301+0000] {subprocess.py:106} INFO -     raise err
[2025-04-11T08:36:21.301+0000] {subprocess.py:106} INFO -   File "/home/***/.local/lib/python3.11/site-packages/urllib3/util/connection.py", line 73, in create_connection
[2025-04-11T08:36:21.302+0000] {subprocess.py:106} INFO -     sock.connect(sa)
[2025-04-11T08:36:21.302+0000] {subprocess.py:106} INFO - ConnectionRefusedError: [Errno 111] Connection refused
[2025-04-11T08:36:21.302+0000] {subprocess.py:106} INFO - 
[2025-04-11T08:36:21.303+0000] {subprocess.py:106} INFO - The above exception was the direct cause of the following exception:
[2025-04-11T08:36:21.303+0000] {subprocess.py:106} INFO - 
[2025-04-11T08:36:21.303+0000] {subprocess.py:106} INFO - Traceback (most recent call last):
[2025-04-11T08:36:21.304+0000] {subprocess.py:106} INFO -   File "/home/***/.local/lib/python3.11/site-packages/urllib3/connectionpool.py", line 787, in urlopen
[2025-04-11T08:36:21.304+0000] {subprocess.py:106} INFO -     response = self._make_request(
[2025-04-11T08:36:21.305+0000] {subprocess.py:106} INFO -                ^^^^^^^^^^^^^^^^^^^
[2025-04-11T08:36:21.305+0000] {subprocess.py:106} INFO -   File "/home/***/.local/lib/python3.11/site-packages/urllib3/connectionpool.py", line 493, in _make_request
[2025-04-11T08:36:21.305+0000] {subprocess.py:106} INFO -     conn.request(
[2025-04-11T08:36:21.306+0000] {subprocess.py:106} INFO -   File "/home/***/.local/lib/python3.11/site-packages/urllib3/connection.py", line 445, in request
[2025-04-11T08:36:21.306+0000] {subprocess.py:106} INFO -     self.endheaders()
[2025-04-11T08:36:21.307+0000] {subprocess.py:106} INFO -   File "/usr/local/lib/python3.11/http/client.py", line 1293, in endheaders
[2025-04-11T08:36:21.307+0000] {subprocess.py:106} INFO -     self._send_output(message_body, encode_chunked=encode_chunked)
[2025-04-11T08:36:21.307+0000] {subprocess.py:106} INFO -   File "/usr/local/lib/python3.11/http/client.py", line 1052, in _send_output
[2025-04-11T08:36:21.308+0000] {subprocess.py:106} INFO -     self.send(msg)
[2025-04-11T08:36:21.308+0000] {subprocess.py:106} INFO -   File "/usr/local/lib/python3.11/http/client.py", line 990, in send
[2025-04-11T08:36:21.309+0000] {subprocess.py:106} INFO -     self.connect()
[2025-04-11T08:36:21.309+0000] {subprocess.py:106} INFO -   File "/home/***/.local/lib/python3.11/site-packages/urllib3/connection.py", line 276, in connect
[2025-04-11T08:36:21.309+0000] {subprocess.py:106} INFO -     self.sock = self._new_conn()
[2025-04-11T08:36:21.310+0000] {subprocess.py:106} INFO -                 ^^^^^^^^^^^^^^^^
[2025-04-11T08:36:21.310+0000] {subprocess.py:106} INFO -   File "/home/***/.local/lib/python3.11/site-packages/urllib3/connection.py", line 213, in _new_conn
[2025-04-11T08:36:21.311+0000] {subprocess.py:106} INFO -     raise NewConnectionError(
[2025-04-11T08:36:21.311+0000] {subprocess.py:106} INFO - urllib3.exceptions.NewConnectionError: <urllib3.connection.HTTPConnection object at 0x7f574c28ca10>: Failed to establish a new connection: [Errno 111] Connection refused
[2025-04-11T08:36:21.312+0000] {subprocess.py:106} INFO - 
[2025-04-11T08:36:21.312+0000] {subprocess.py:106} INFO - The above exception was the direct cause of the following exception:
[2025-04-11T08:36:21.312+0000] {subprocess.py:106} INFO - 
[2025-04-11T08:36:21.313+0000] {subprocess.py:106} INFO - Traceback (most recent call last):
[2025-04-11T08:36:21.313+0000] {subprocess.py:106} INFO -   File "/home/***/.local/lib/python3.11/site-packages/requests/adapters.py", line 667, in send
[2025-04-11T08:36:21.313+0000] {subprocess.py:106} INFO -     resp = conn.urlopen(
[2025-04-11T08:36:21.314+0000] {subprocess.py:106} INFO -            ^^^^^^^^^^^^^
[2025-04-11T08:36:21.315+0000] {subprocess.py:106} INFO -   File "/home/***/.local/lib/python3.11/site-packages/urllib3/connectionpool.py", line 871, in urlopen
[2025-04-11T08:36:21.315+0000] {subprocess.py:106} INFO -     return self.urlopen(
[2025-04-11T08:36:21.316+0000] {subprocess.py:106} INFO -            ^^^^^^^^^^^^^
[2025-04-11T08:36:21.316+0000] {subprocess.py:106} INFO -   File "/home/***/.local/lib/python3.11/site-packages/urllib3/connectionpool.py", line 871, in urlopen
[2025-04-11T08:36:21.316+0000] {subprocess.py:106} INFO -     return self.urlopen(
[2025-04-11T08:36:21.317+0000] {subprocess.py:106} INFO -            ^^^^^^^^^^^^^
[2025-04-11T08:36:21.317+0000] {subprocess.py:106} INFO -   File "/home/***/.local/lib/python3.11/site-packages/urllib3/connectionpool.py", line 871, in urlopen
[2025-04-11T08:36:21.317+0000] {subprocess.py:106} INFO -     return self.urlopen(
[2025-04-11T08:36:21.318+0000] {subprocess.py:106} INFO -            ^^^^^^^^^^^^^
[2025-04-11T08:36:21.318+0000] {subprocess.py:106} INFO -   [Previous line repeated 4 more times]
[2025-04-11T08:36:21.319+0000] {subprocess.py:106} INFO -   File "/home/***/.local/lib/python3.11/site-packages/urllib3/connectionpool.py", line 841, in urlopen
[2025-04-11T08:36:21.319+0000] {subprocess.py:106} INFO -     retries = retries.increment(
[2025-04-11T08:36:21.319+0000] {subprocess.py:106} INFO -               ^^^^^^^^^^^^^^^^^^
[2025-04-11T08:36:21.320+0000] {subprocess.py:106} INFO -   File "/home/***/.local/lib/python3.11/site-packages/urllib3/util/retry.py", line 519, in increment
[2025-04-11T08:36:21.320+0000] {subprocess.py:106} INFO -     raise MaxRetryError(_pool, url, reason) from reason  # type: ignore[arg-type]
[2025-04-11T08:36:21.320+0000] {subprocess.py:106} INFO -     ^^^^^^^^^^^^^^^^^^^^^^^^^^^^^^^^^^^^^^^^^^^^^^^^^^^
[2025-04-11T08:36:21.321+0000] {subprocess.py:106} INFO - urllib3.exceptions.MaxRetryError: HTTPConnectionPool(host='localhost', port=5001): Max retries exceeded with url: /api/2.0/mlflow/experiments/get-by-name?experiment_name=Stock_Price_Prediction_LSTM_Refactored (Caused by NewConnectionError('<urllib3.connection.HTTPConnection object at 0x7f574c28ca10>: Failed to establish a new connection: [Errno 111] Connection refused'))
[2025-04-11T08:36:21.321+0000] {subprocess.py:106} INFO - 
[2025-04-11T08:36:21.322+0000] {subprocess.py:106} INFO - During handling of the above exception, another exception occurred:
[2025-04-11T08:36:21.322+0000] {subprocess.py:106} INFO - 
[2025-04-11T08:36:21.322+0000] {subprocess.py:106} INFO - Traceback (most recent call last):
[2025-04-11T08:36:21.323+0000] {subprocess.py:106} INFO -   File "/home/***/.local/lib/python3.11/site-packages/mlflow/utils/rest_utils.py", line 181, in http_request
[2025-04-11T08:36:21.323+0000] {subprocess.py:106} INFO -     return _get_http_response_with_retries(
[2025-04-11T08:36:21.324+0000] {subprocess.py:106} INFO -            ^^^^^^^^^^^^^^^^^^^^^^^^^^^^^^^^
[2025-04-11T08:36:21.324+0000] {subprocess.py:106} INFO -   File "/home/***/.local/lib/python3.11/site-packages/mlflow/utils/request_utils.py", line 237, in _get_http_response_with_retries
[2025-04-11T08:36:21.324+0000] {subprocess.py:106} INFO -     return session.request(method, url, allow_redirects=allow_redirects, **kwargs)
[2025-04-11T08:36:21.325+0000] {subprocess.py:106} INFO -            ^^^^^^^^^^^^^^^^^^^^^^^^^^^^^^^^^^^^^^^^^^^^^^^^^^^^^^^^^^^^^^^^^^^^^^^
[2025-04-11T08:36:21.325+0000] {subprocess.py:106} INFO -   File "/home/***/.local/lib/python3.11/site-packages/requests/sessions.py", line 589, in request
[2025-04-11T08:36:21.325+0000] {subprocess.py:106} INFO -     resp = self.send(prep, **send_kwargs)
[2025-04-11T08:36:21.326+0000] {subprocess.py:106} INFO -            ^^^^^^^^^^^^^^^^^^^^^^^^^^^^^^
[2025-04-11T08:36:21.326+0000] {subprocess.py:106} INFO -   File "/home/***/.local/lib/python3.11/site-packages/requests/sessions.py", line 703, in send
[2025-04-11T08:36:21.327+0000] {subprocess.py:106} INFO -     r = adapter.send(request, **kwargs)
[2025-04-11T08:36:21.327+0000] {subprocess.py:106} INFO -         ^^^^^^^^^^^^^^^^^^^^^^^^^^^^^^^
[2025-04-11T08:36:21.327+0000] {subprocess.py:106} INFO -   File "/home/***/.local/lib/python3.11/site-packages/requests/adapters.py", line 700, in send
[2025-04-11T08:36:21.328+0000] {subprocess.py:106} INFO -     raise ConnectionError(e, request=request)
[2025-04-11T08:36:21.328+0000] {subprocess.py:106} INFO - requests.exceptions.ConnectionError: HTTPConnectionPool(host='localhost', port=5001): Max retries exceeded with url: /api/2.0/mlflow/experiments/get-by-name?experiment_name=Stock_Price_Prediction_LSTM_Refactored (Caused by NewConnectionError('<urllib3.connection.HTTPConnection object at 0x7f574c28ca10>: Failed to establish a new connection: [Errno 111] Connection refused'))
[2025-04-11T08:36:21.329+0000] {subprocess.py:106} INFO - 
[2025-04-11T08:36:21.329+0000] {subprocess.py:106} INFO - During handling of the above exception, another exception occurred:
[2025-04-11T08:36:21.330+0000] {subprocess.py:106} INFO - 
[2025-04-11T08:36:21.330+0000] {subprocess.py:106} INFO - Traceback (most recent call last):
[2025-04-11T08:36:21.330+0000] {subprocess.py:106} INFO -   File "/opt/***/src/models/train_model.py", line 240, in <module>
[2025-04-11T08:36:21.331+0000] {subprocess.py:106} INFO -     run_training(args.config)
[2025-04-11T08:36:21.331+0000] {subprocess.py:106} INFO -   File "/opt/***/src/models/train_model.py", line 214, in run_training
[2025-04-11T08:36:21.332+0000] {subprocess.py:106} INFO -     mlflow.set_experiment(mlflow_experiment)
[2025-04-11T08:36:21.332+0000] {subprocess.py:106} INFO -   File "/home/***/.local/lib/python3.11/site-packages/mlflow/tracking/fluent.py", line 157, in set_experiment
[2025-04-11T08:36:21.332+0000] {subprocess.py:106} INFO -     experiment = client.get_experiment_by_name(experiment_name)
[2025-04-11T08:36:21.333+0000] {subprocess.py:106} INFO -                  ^^^^^^^^^^^^^^^^^^^^^^^^^^^^^^^^^^^^^^^^^^^^^^
[2025-04-11T08:36:21.333+0000] {subprocess.py:106} INFO -   File "/home/***/.local/lib/python3.11/site-packages/mlflow/tracking/client.py", line 1698, in get_experiment_by_name
[2025-04-11T08:36:21.333+0000] {subprocess.py:106} INFO -     return self._tracking_client.get_experiment_by_name(name)
[2025-04-11T08:36:21.334+0000] {subprocess.py:106} INFO -            ^^^^^^^^^^^^^^^^^^^^^^^^^^^^^^^^^^^^^^^^^^^^^^^^^^
[2025-04-11T08:36:21.334+0000] {subprocess.py:106} INFO -   File "/home/***/.local/lib/python3.11/site-packages/mlflow/tracking/_tracking_service/client.py", line 586, in get_experiment_by_name
[2025-04-11T08:36:21.336+0000] {subprocess.py:106} INFO -     return self.store.get_experiment_by_name(name)
[2025-04-11T08:36:21.337+0000] {subprocess.py:106} INFO -            ^^^^^^^^^^^^^^^^^^^^^^^^^^^^^^^^^^^^^^^
[2025-04-11T08:36:21.337+0000] {subprocess.py:106} INFO -   File "/home/***/.local/lib/python3.11/site-packages/mlflow/store/tracking/rest_store.py", line 641, in get_experiment_by_name
[2025-04-11T08:36:21.337+0000] {subprocess.py:106} INFO -     response_proto = self._call_endpoint(GetExperimentByName, req_body)
[2025-04-11T08:36:21.338+0000] {subprocess.py:106} INFO -                      ^^^^^^^^^^^^^^^^^^^^^^^^^^^^^^^^^^^^^^^^^^^^^^^^^^
[2025-04-11T08:36:21.338+0000] {subprocess.py:106} INFO -   File "/home/***/.local/lib/python3.11/site-packages/mlflow/store/tracking/rest_store.py", line 90, in _call_endpoint
[2025-04-11T08:36:21.338+0000] {subprocess.py:106} INFO -     return call_endpoint(self.get_host_creds(), endpoint, method, json_body, response_proto)
[2025-04-11T08:36:21.339+0000] {subprocess.py:106} INFO -            ^^^^^^^^^^^^^^^^^^^^^^^^^^^^^^^^^^^^^^^^^^^^^^^^^^^^^^^^^^^^^^^^^^^^^^^^^^^^^^^^^
[2025-04-11T08:36:21.339+0000] {subprocess.py:106} INFO -   File "/home/***/.local/lib/python3.11/site-packages/mlflow/utils/rest_utils.py", line 387, in call_endpoint
[2025-04-11T08:36:21.339+0000] {subprocess.py:106} INFO -     response = http_request(**call_kwargs)
[2025-04-11T08:36:21.340+0000] {subprocess.py:106} INFO -                ^^^^^^^^^^^^^^^^^^^^^^^^^^^
[2025-04-11T08:36:21.340+0000] {subprocess.py:106} INFO -   File "/home/***/.local/lib/python3.11/site-packages/mlflow/utils/rest_utils.py", line 204, in http_request
[2025-04-11T08:36:21.340+0000] {subprocess.py:106} INFO -     raise MlflowException(f"API request to {url} failed with exception {e}")
[2025-04-11T08:36:21.341+0000] {subprocess.py:106} INFO - mlflow.exceptions.MlflowException: API request to http://localhost:5001/api/2.0/mlflow/experiments/get-by-name failed with exception HTTPConnectionPool(host='localhost', port=5001): Max retries exceeded with url: /api/2.0/mlflow/experiments/get-by-name?experiment_name=Stock_Price_Prediction_LSTM_Refactored (Caused by NewConnectionError('<urllib3.connection.HTTPConnection object at 0x7f574c28ca10>: Failed to establish a new connection: [Errno 111] Connection refused'))
[2025-04-11T08:36:21.864+0000] {subprocess.py:110} INFO - Command exited with return code 1
[2025-04-11T08:36:21.871+0000] {taskinstance.py:3313} ERROR - Task failed with exception
Traceback (most recent call last):
  File "/home/airflow/.local/lib/python3.11/site-packages/airflow/models/taskinstance.py", line 768, in _execute_task
    result = _execute_callable(context=context, **execute_callable_kwargs)
             ^^^^^^^^^^^^^^^^^^^^^^^^^^^^^^^^^^^^^^^^^^^^^^^^^^^^^^^^^^^^^
  File "/home/airflow/.local/lib/python3.11/site-packages/airflow/models/taskinstance.py", line 734, in _execute_callable
    return ExecutionCallableRunner(
           ^^^^^^^^^^^^^^^^^^^^^^^^
  File "/home/airflow/.local/lib/python3.11/site-packages/airflow/utils/operator_helpers.py", line 252, in run
    return self.func(*args, **kwargs)
           ^^^^^^^^^^^^^^^^^^^^^^^^^^
  File "/home/airflow/.local/lib/python3.11/site-packages/airflow/models/baseoperator.py", line 424, in wrapper
    return func(self, *args, **kwargs)
           ^^^^^^^^^^^^^^^^^^^^^^^^^^^
  File "/home/airflow/.local/lib/python3.11/site-packages/airflow/operators/bash.py", line 276, in execute
    raise AirflowException(
airflow.exceptions.AirflowException: Bash command failed. The command returned a non-zero exit code 1.
[2025-04-11T08:36:21.876+0000] {taskinstance.py:1226} INFO - Marking task as UP_FOR_RETRY. dag_id=lstm_stock_prediction_refactored, task_id=train_final_model, run_id=manual__2025-04-11T07:34:50.523738+00:00, execution_date=20250411T073450, start_date=20250411T083209, end_date=20250411T083621
[2025-04-11T08:36:21.896+0000] {taskinstance.py:341} INFO - ::group::Post task execution logs
[2025-04-11T08:36:21.898+0000] {standard_task_runner.py:124} ERROR - Failed to execute job 33 for task train_final_model (Bash command failed. The command returned a non-zero exit code 1.; 222)
Traceback (most recent call last):
  File "/home/airflow/.local/lib/python3.11/site-packages/airflow/task/task_runner/standard_task_runner.py", line 117, in _start_by_fork
    ret = args.func(args, dag=self.dag)
          ^^^^^^^^^^^^^^^^^^^^^^^^^^^^^
  File "/home/airflow/.local/lib/python3.11/site-packages/airflow/cli/cli_config.py", line 49, in command
    return func(*args, **kwargs)
           ^^^^^^^^^^^^^^^^^^^^^
  File "/home/airflow/.local/lib/python3.11/site-packages/airflow/utils/cli.py", line 116, in wrapper
    return f(*args, **kwargs)
           ^^^^^^^^^^^^^^^^^^
  File "/home/airflow/.local/lib/python3.11/site-packages/airflow/cli/commands/task_command.py", line 483, in task_run
    task_return_code = _run_task_by_selected_method(args, _dag, ti)
                       ^^^^^^^^^^^^^^^^^^^^^^^^^^^^^^^^^^^^^^^^^^^^
  File "/home/airflow/.local/lib/python3.11/site-packages/airflow/cli/commands/task_command.py", line 256, in _run_task_by_selected_method
    return _run_raw_task(args, ti)
           ^^^^^^^^^^^^^^^^^^^^^^^
  File "/home/airflow/.local/lib/python3.11/site-packages/airflow/cli/commands/task_command.py", line 341, in _run_raw_task
    return ti._run_raw_task(
           ^^^^^^^^^^^^^^^^^
  File "/home/airflow/.local/lib/python3.11/site-packages/airflow/utils/session.py", line 97, in wrapper
    return func(*args, session=session, **kwargs)
           ^^^^^^^^^^^^^^^^^^^^^^^^^^^^^^^^^^^^^^
  File "/home/airflow/.local/lib/python3.11/site-packages/airflow/models/taskinstance.py", line 3006, in _run_raw_task
    return _run_raw_task(
           ^^^^^^^^^^^^^^
  File "/home/airflow/.local/lib/python3.11/site-packages/airflow/models/taskinstance.py", line 274, in _run_raw_task
    TaskInstance._execute_task_with_callbacks(
  File "/home/airflow/.local/lib/python3.11/site-packages/airflow/models/taskinstance.py", line 3161, in _execute_task_with_callbacks
    result = self._execute_task(context, task_orig)
             ^^^^^^^^^^^^^^^^^^^^^^^^^^^^^^^^^^^^^^
  File "/home/airflow/.local/lib/python3.11/site-packages/airflow/models/taskinstance.py", line 3185, in _execute_task
    return _execute_task(self, context, task_orig)
           ^^^^^^^^^^^^^^^^^^^^^^^^^^^^^^^^^^^^^^^
  File "/home/airflow/.local/lib/python3.11/site-packages/airflow/models/taskinstance.py", line 768, in _execute_task
    result = _execute_callable(context=context, **execute_callable_kwargs)
             ^^^^^^^^^^^^^^^^^^^^^^^^^^^^^^^^^^^^^^^^^^^^^^^^^^^^^^^^^^^^^
  File "/home/airflow/.local/lib/python3.11/site-packages/airflow/models/taskinstance.py", line 734, in _execute_callable
    return ExecutionCallableRunner(
           ^^^^^^^^^^^^^^^^^^^^^^^^
  File "/home/airflow/.local/lib/python3.11/site-packages/airflow/utils/operator_helpers.py", line 252, in run
    return self.func(*args, **kwargs)
           ^^^^^^^^^^^^^^^^^^^^^^^^^^
  File "/home/airflow/.local/lib/python3.11/site-packages/airflow/models/baseoperator.py", line 424, in wrapper
    return func(self, *args, **kwargs)
           ^^^^^^^^^^^^^^^^^^^^^^^^^^^
  File "/home/airflow/.local/lib/python3.11/site-packages/airflow/operators/bash.py", line 276, in execute
    raise AirflowException(
airflow.exceptions.AirflowException: Bash command failed. The command returned a non-zero exit code 1.
[2025-04-11T08:36:21.924+0000] {local_task_job_runner.py:266} INFO - Task exited with return code 1
[2025-04-11T08:36:21.941+0000] {taskinstance.py:3901} INFO - 0 downstream tasks scheduled from follow-on schedule check
[2025-04-11T08:36:21.944+0000] {local_task_job_runner.py:245} INFO - ::endgroup::
