[2025-04-11T07:41:24.597+0000] {local_task_job_runner.py:123} INFO - ::group::Pre task execution logs
[2025-04-11T07:41:24.616+0000] {taskinstance.py:2614} INFO - Dependencies all met for dep_context=non-requeueable deps ti=<TaskInstance: lstm_stock_prediction_refactored.train_final_model manual__2025-04-11T07:34:50.523738+00:00 [queued]>
[2025-04-11T07:41:24.622+0000] {taskinstance.py:2614} INFO - Dependencies all met for dep_context=requeueable deps ti=<TaskInstance: lstm_stock_prediction_refactored.train_final_model manual__2025-04-11T07:34:50.523738+00:00 [queued]>
[2025-04-11T07:41:24.623+0000] {taskinstance.py:2867} INFO - Starting attempt 2 of 2
[2025-04-11T07:41:24.632+0000] {taskinstance.py:2890} INFO - Executing <Task(BashOperator): train_final_model> on 2025-04-11 07:34:50.523738+00:00
[2025-04-11T07:41:24.636+0000] {standard_task_runner.py:72} INFO - Started process 465 to run task
[2025-04-11T07:41:24.638+0000] {standard_task_runner.py:104} INFO - Running: ['***', 'tasks', 'run', 'lstm_stock_prediction_refactored', 'train_final_model', 'manual__2025-04-11T07:34:50.523738+00:00', '--job-id', '25', '--raw', '--subdir', 'DAGS_FOLDER/lstm_refactored_dag.py', '--cfg-path', '/tmp/tmp94f571vq']
[2025-04-11T07:41:24.640+0000] {standard_task_runner.py:105} INFO - Job 25: Subtask train_final_model
[2025-04-11T07:41:24.682+0000] {task_command.py:467} INFO - Running <TaskInstance: lstm_stock_prediction_refactored.train_final_model manual__2025-04-11T07:34:50.523738+00:00 [running]> on host e3a30e77acd1
[2025-04-11T07:41:24.754+0000] {taskinstance.py:3134} INFO - Exporting env vars: AIRFLOW_CTX_DAG_OWNER='***_team' AIRFLOW_CTX_DAG_ID='lstm_stock_prediction_refactored' AIRFLOW_CTX_TASK_ID='train_final_model' AIRFLOW_CTX_EXECUTION_DATE='2025-04-11T07:34:50.523738+00:00' AIRFLOW_CTX_TRY_NUMBER='2' AIRFLOW_CTX_DAG_RUN_ID='manual__2025-04-11T07:34:50.523738+00:00'
[2025-04-11T07:41:24.755+0000] {taskinstance.py:732} INFO - ::endgroup::
[2025-04-11T07:41:24.765+0000] {subprocess.py:78} INFO - Tmp dir root location: /tmp
[2025-04-11T07:41:24.767+0000] {subprocess.py:88} INFO - Running command: ['/usr/bin/bash', '-c', 'python /opt/***/src/models/train_model.py --config /opt/***/config/params.yaml']
[2025-04-11T07:41:24.774+0000] {subprocess.py:99} INFO - Output:
[2025-04-11T07:45:35.252+0000] {subprocess.py:106} INFO - Using device: cpu
[2025-04-11T07:45:35.254+0000] {subprocess.py:106} INFO - --- Loading Scaled Data from /opt/***/data/features/split_scaled_data.npz ---
[2025-04-11T07:45:35.256+0000] {subprocess.py:106} INFO - --- Finished Loading Scaled Data ---
[2025-04-11T07:45:35.257+0000] {subprocess.py:106} INFO - --- Loading Scalers from /opt/***/data/processed/scalers.pkl ---
[2025-04-11T07:45:35.258+0000] {subprocess.py:106} INFO - --- Finished Loading Scalers ---
[2025-04-11T07:45:35.258+0000] {subprocess.py:106} INFO - --- Loading Tickers from /opt/***/data/processed/all_processed_data.npz ---
[2025-04-11T07:45:35.259+0000] {subprocess.py:106} INFO - Tickers: ['AAPL', 'MA', 'CSCO', 'MSFT', 'AMZN', 'GOOG', 'IBM']
[2025-04-11T07:45:35.260+0000] {subprocess.py:106} INFO - --- Finished Loading Tickers ---
[2025-04-11T07:45:35.260+0000] {subprocess.py:106} INFO - --- Loading Best Hyperparameters from /opt/***/config/best_params.json ---
[2025-04-11T07:45:35.261+0000] {subprocess.py:106} INFO - Best parameters loaded: {'batch_size': 80, 'hidden_size': 64, 'num_layers': 2, 'dropout_rate': 0.4, 'learning_rate': 0.00010587273351810358, 'model_type': 'lstm_cross_attention'}
[2025-04-11T07:45:35.261+0000] {subprocess.py:106} INFO - --- Finished Loading Best Hyperparameters ---
[2025-04-11T07:45:35.262+0000] {subprocess.py:106} INFO - --- Setting MLflow Experiment: Stock_Price_Prediction_LSTM_Refactored ---
[2025-04-11T07:45:35.263+0000] {subprocess.py:106} INFO - Using MLflow Tracking URI: http://localhost:5001/
[2025-04-11T07:45:35.264+0000] {subprocess.py:106} INFO - Traceback (most recent call last):
[2025-04-11T07:45:35.264+0000] {subprocess.py:106} INFO -   File "/home/***/.local/lib/python3.11/site-packages/urllib3/connection.py", line 198, in _new_conn
[2025-04-11T07:45:35.265+0000] {subprocess.py:106} INFO -     sock = connection.create_connection(
[2025-04-11T07:45:35.266+0000] {subprocess.py:106} INFO -            ^^^^^^^^^^^^^^^^^^^^^^^^^^^^^
[2025-04-11T07:45:35.267+0000] {subprocess.py:106} INFO -   File "/home/***/.local/lib/python3.11/site-packages/urllib3/util/connection.py", line 85, in create_connection
[2025-04-11T07:45:35.267+0000] {subprocess.py:106} INFO -     raise err
[2025-04-11T07:45:35.268+0000] {subprocess.py:106} INFO -   File "/home/***/.local/lib/python3.11/site-packages/urllib3/util/connection.py", line 73, in create_connection
[2025-04-11T07:45:35.268+0000] {subprocess.py:106} INFO -     sock.connect(sa)
[2025-04-11T07:45:35.269+0000] {subprocess.py:106} INFO - ConnectionRefusedError: [Errno 111] Connection refused
[2025-04-11T07:45:35.269+0000] {subprocess.py:106} INFO - 
[2025-04-11T07:45:35.270+0000] {subprocess.py:106} INFO - The above exception was the direct cause of the following exception:
[2025-04-11T07:45:35.270+0000] {subprocess.py:106} INFO - 
[2025-04-11T07:45:35.271+0000] {subprocess.py:106} INFO - Traceback (most recent call last):
[2025-04-11T07:45:35.271+0000] {subprocess.py:106} INFO -   File "/home/***/.local/lib/python3.11/site-packages/urllib3/connectionpool.py", line 787, in urlopen
[2025-04-11T07:45:35.271+0000] {subprocess.py:106} INFO -     response = self._make_request(
[2025-04-11T07:45:35.272+0000] {subprocess.py:106} INFO -                ^^^^^^^^^^^^^^^^^^^
[2025-04-11T07:45:35.272+0000] {subprocess.py:106} INFO -   File "/home/***/.local/lib/python3.11/site-packages/urllib3/connectionpool.py", line 493, in _make_request
[2025-04-11T07:45:35.273+0000] {subprocess.py:106} INFO -     conn.request(
[2025-04-11T07:45:35.273+0000] {subprocess.py:106} INFO -   File "/home/***/.local/lib/python3.11/site-packages/urllib3/connection.py", line 445, in request
[2025-04-11T07:45:35.273+0000] {subprocess.py:106} INFO -     self.endheaders()
[2025-04-11T07:45:35.274+0000] {subprocess.py:106} INFO -   File "/usr/local/lib/python3.11/http/client.py", line 1293, in endheaders
[2025-04-11T07:45:35.274+0000] {subprocess.py:106} INFO -     self._send_output(message_body, encode_chunked=encode_chunked)
[2025-04-11T07:45:35.274+0000] {subprocess.py:106} INFO -   File "/usr/local/lib/python3.11/http/client.py", line 1052, in _send_output
[2025-04-11T07:45:35.275+0000] {subprocess.py:106} INFO -     self.send(msg)
[2025-04-11T07:45:35.275+0000] {subprocess.py:106} INFO -   File "/usr/local/lib/python3.11/http/client.py", line 990, in send
[2025-04-11T07:45:35.276+0000] {subprocess.py:106} INFO -     self.connect()
[2025-04-11T07:45:35.276+0000] {subprocess.py:106} INFO -   File "/home/***/.local/lib/python3.11/site-packages/urllib3/connection.py", line 276, in connect
[2025-04-11T07:45:35.276+0000] {subprocess.py:106} INFO -     self.sock = self._new_conn()
[2025-04-11T07:45:35.277+0000] {subprocess.py:106} INFO -                 ^^^^^^^^^^^^^^^^
[2025-04-11T07:45:35.277+0000] {subprocess.py:106} INFO -   File "/home/***/.local/lib/python3.11/site-packages/urllib3/connection.py", line 213, in _new_conn
[2025-04-11T07:45:35.277+0000] {subprocess.py:106} INFO -     raise NewConnectionError(
[2025-04-11T07:45:35.278+0000] {subprocess.py:106} INFO - urllib3.exceptions.NewConnectionError: <urllib3.connection.HTTPConnection object at 0x7f1fbe1d8750>: Failed to establish a new connection: [Errno 111] Connection refused
[2025-04-11T07:45:35.278+0000] {subprocess.py:106} INFO - 
[2025-04-11T07:45:35.278+0000] {subprocess.py:106} INFO - The above exception was the direct cause of the following exception:
[2025-04-11T07:45:35.279+0000] {subprocess.py:106} INFO - 
[2025-04-11T07:45:35.279+0000] {subprocess.py:106} INFO - Traceback (most recent call last):
[2025-04-11T07:45:35.280+0000] {subprocess.py:106} INFO -   File "/home/***/.local/lib/python3.11/site-packages/requests/adapters.py", line 667, in send
[2025-04-11T07:45:35.280+0000] {subprocess.py:106} INFO -     resp = conn.urlopen(
[2025-04-11T07:45:35.281+0000] {subprocess.py:106} INFO -            ^^^^^^^^^^^^^
[2025-04-11T07:45:35.282+0000] {subprocess.py:106} INFO -   File "/home/***/.local/lib/python3.11/site-packages/urllib3/connectionpool.py", line 871, in urlopen
[2025-04-11T07:45:35.282+0000] {subprocess.py:106} INFO -     return self.urlopen(
[2025-04-11T07:45:35.283+0000] {subprocess.py:106} INFO -            ^^^^^^^^^^^^^
[2025-04-11T07:45:35.283+0000] {subprocess.py:106} INFO -   File "/home/***/.local/lib/python3.11/site-packages/urllib3/connectionpool.py", line 871, in urlopen
[2025-04-11T07:45:35.283+0000] {subprocess.py:106} INFO -     return self.urlopen(
[2025-04-11T07:45:35.284+0000] {subprocess.py:106} INFO -            ^^^^^^^^^^^^^
[2025-04-11T07:45:35.284+0000] {subprocess.py:106} INFO -   File "/home/***/.local/lib/python3.11/site-packages/urllib3/connectionpool.py", line 871, in urlopen
[2025-04-11T07:45:35.284+0000] {subprocess.py:106} INFO -     return self.urlopen(
[2025-04-11T07:45:35.285+0000] {subprocess.py:106} INFO -            ^^^^^^^^^^^^^
[2025-04-11T07:45:35.285+0000] {subprocess.py:106} INFO -   [Previous line repeated 4 more times]
[2025-04-11T07:45:35.286+0000] {subprocess.py:106} INFO -   File "/home/***/.local/lib/python3.11/site-packages/urllib3/connectionpool.py", line 841, in urlopen
[2025-04-11T07:45:35.286+0000] {subprocess.py:106} INFO -     retries = retries.increment(
[2025-04-11T07:45:35.286+0000] {subprocess.py:106} INFO -               ^^^^^^^^^^^^^^^^^^
[2025-04-11T07:45:35.287+0000] {subprocess.py:106} INFO -   File "/home/***/.local/lib/python3.11/site-packages/urllib3/util/retry.py", line 519, in increment
[2025-04-11T07:45:35.287+0000] {subprocess.py:106} INFO -     raise MaxRetryError(_pool, url, reason) from reason  # type: ignore[arg-type]
[2025-04-11T07:45:35.287+0000] {subprocess.py:106} INFO -     ^^^^^^^^^^^^^^^^^^^^^^^^^^^^^^^^^^^^^^^^^^^^^^^^^^^
[2025-04-11T07:45:35.288+0000] {subprocess.py:106} INFO - urllib3.exceptions.MaxRetryError: HTTPConnectionPool(host='localhost', port=5001): Max retries exceeded with url: /api/2.0/mlflow/experiments/get-by-name?experiment_name=Stock_Price_Prediction_LSTM_Refactored (Caused by NewConnectionError('<urllib3.connection.HTTPConnection object at 0x7f1fbe1d8750>: Failed to establish a new connection: [Errno 111] Connection refused'))
[2025-04-11T07:45:35.288+0000] {subprocess.py:106} INFO - 
[2025-04-11T07:45:35.288+0000] {subprocess.py:106} INFO - During handling of the above exception, another exception occurred:
[2025-04-11T07:45:35.289+0000] {subprocess.py:106} INFO - 
[2025-04-11T07:45:35.289+0000] {subprocess.py:106} INFO - Traceback (most recent call last):
[2025-04-11T07:45:35.289+0000] {subprocess.py:106} INFO -   File "/home/***/.local/lib/python3.11/site-packages/mlflow/utils/rest_utils.py", line 181, in http_request
[2025-04-11T07:45:35.290+0000] {subprocess.py:106} INFO -     return _get_http_response_with_retries(
[2025-04-11T07:45:35.290+0000] {subprocess.py:106} INFO -            ^^^^^^^^^^^^^^^^^^^^^^^^^^^^^^^^
[2025-04-11T07:45:35.290+0000] {subprocess.py:106} INFO -   File "/home/***/.local/lib/python3.11/site-packages/mlflow/utils/request_utils.py", line 237, in _get_http_response_with_retries
[2025-04-11T07:45:35.291+0000] {subprocess.py:106} INFO -     return session.request(method, url, allow_redirects=allow_redirects, **kwargs)
[2025-04-11T07:45:35.291+0000] {subprocess.py:106} INFO -            ^^^^^^^^^^^^^^^^^^^^^^^^^^^^^^^^^^^^^^^^^^^^^^^^^^^^^^^^^^^^^^^^^^^^^^^
[2025-04-11T07:45:35.292+0000] {subprocess.py:106} INFO -   File "/home/***/.local/lib/python3.11/site-packages/requests/sessions.py", line 589, in request
[2025-04-11T07:45:35.292+0000] {subprocess.py:106} INFO -     resp = self.send(prep, **send_kwargs)
[2025-04-11T07:45:35.292+0000] {subprocess.py:106} INFO -            ^^^^^^^^^^^^^^^^^^^^^^^^^^^^^^
[2025-04-11T07:45:35.293+0000] {subprocess.py:106} INFO -   File "/home/***/.local/lib/python3.11/site-packages/requests/sessions.py", line 703, in send
[2025-04-11T07:45:35.293+0000] {subprocess.py:106} INFO -     r = adapter.send(request, **kwargs)
[2025-04-11T07:45:35.293+0000] {subprocess.py:106} INFO -         ^^^^^^^^^^^^^^^^^^^^^^^^^^^^^^^
[2025-04-11T07:45:35.294+0000] {subprocess.py:106} INFO -   File "/home/***/.local/lib/python3.11/site-packages/requests/adapters.py", line 700, in send
[2025-04-11T07:45:35.294+0000] {subprocess.py:106} INFO -     raise ConnectionError(e, request=request)
[2025-04-11T07:45:35.295+0000] {subprocess.py:106} INFO - requests.exceptions.ConnectionError: HTTPConnectionPool(host='localhost', port=5001): Max retries exceeded with url: /api/2.0/mlflow/experiments/get-by-name?experiment_name=Stock_Price_Prediction_LSTM_Refactored (Caused by NewConnectionError('<urllib3.connection.HTTPConnection object at 0x7f1fbe1d8750>: Failed to establish a new connection: [Errno 111] Connection refused'))
[2025-04-11T07:45:35.295+0000] {subprocess.py:106} INFO - 
[2025-04-11T07:45:35.296+0000] {subprocess.py:106} INFO - During handling of the above exception, another exception occurred:
[2025-04-11T07:45:35.296+0000] {subprocess.py:106} INFO - 
[2025-04-11T07:45:35.296+0000] {subprocess.py:106} INFO - Traceback (most recent call last):
[2025-04-11T07:45:35.297+0000] {subprocess.py:106} INFO -   File "/opt/***/src/models/train_model.py", line 238, in <module>
[2025-04-11T07:45:35.297+0000] {subprocess.py:106} INFO -   File "/opt/***/src/models/train_model.py", line 211, in run_training
[2025-04-11T07:45:35.298+0000] {subprocess.py:106} INFO -     mlflow.set_experiment(mlflow_experiment)
[2025-04-11T07:45:35.298+0000] {subprocess.py:106} INFO -   File "/home/***/.local/lib/python3.11/site-packages/mlflow/tracking/fluent.py", line 157, in set_experiment
[2025-04-11T07:45:35.298+0000] {subprocess.py:106} INFO -     experiment = client.get_experiment_by_name(experiment_name)
[2025-04-11T07:45:35.299+0000] {subprocess.py:106} INFO -                  ^^^^^^^^^^^^^^^^^^^^^^^^^^^^^^^^^^^^^^^^^^^^^^
[2025-04-11T07:45:35.299+0000] {subprocess.py:106} INFO -   File "/home/***/.local/lib/python3.11/site-packages/mlflow/tracking/client.py", line 1698, in get_experiment_by_name
[2025-04-11T07:45:35.299+0000] {subprocess.py:106} INFO -     return self._tracking_client.get_experiment_by_name(name)
[2025-04-11T07:45:35.300+0000] {subprocess.py:106} INFO -            ^^^^^^^^^^^^^^^^^^^^^^^^^^^^^^^^^^^^^^^^^^^^^^^^^^
[2025-04-11T07:45:35.300+0000] {subprocess.py:106} INFO -   File "/home/***/.local/lib/python3.11/site-packages/mlflow/tracking/_tracking_service/client.py", line 586, in get_experiment_by_name
[2025-04-11T07:45:35.301+0000] {subprocess.py:106} INFO -     return self.store.get_experiment_by_name(name)
[2025-04-11T07:45:35.301+0000] {subprocess.py:106} INFO -            ^^^^^^^^^^^^^^^^^^^^^^^^^^^^^^^^^^^^^^^
[2025-04-11T07:45:35.301+0000] {subprocess.py:106} INFO -   File "/home/***/.local/lib/python3.11/site-packages/mlflow/store/tracking/rest_store.py", line 641, in get_experiment_by_name
[2025-04-11T07:45:35.302+0000] {subprocess.py:106} INFO -     response_proto = self._call_endpoint(GetExperimentByName, req_body)
[2025-04-11T07:45:35.302+0000] {subprocess.py:106} INFO -                      ^^^^^^^^^^^^^^^^^^^^^^^^^^^^^^^^^^^^^^^^^^^^^^^^^^
[2025-04-11T07:45:35.302+0000] {subprocess.py:106} INFO -   File "/home/***/.local/lib/python3.11/site-packages/mlflow/store/tracking/rest_store.py", line 90, in _call_endpoint
[2025-04-11T07:45:35.303+0000] {subprocess.py:106} INFO -     return call_endpoint(self.get_host_creds(), endpoint, method, json_body, response_proto)
[2025-04-11T07:45:35.303+0000] {subprocess.py:106} INFO -            ^^^^^^^^^^^^^^^^^^^^^^^^^^^^^^^^^^^^^^^^^^^^^^^^^^^^^^^^^^^^^^^^^^^^^^^^^^^^^^^^^
[2025-04-11T07:45:35.303+0000] {subprocess.py:106} INFO -   File "/home/***/.local/lib/python3.11/site-packages/mlflow/utils/rest_utils.py", line 387, in call_endpoint
[2025-04-11T07:45:35.304+0000] {subprocess.py:106} INFO -     response = http_request(**call_kwargs)
[2025-04-11T07:45:35.304+0000] {subprocess.py:106} INFO -                ^^^^^^^^^^^^^^^^^^^^^^^^^^^
[2025-04-11T07:45:35.304+0000] {subprocess.py:106} INFO -   File "/home/***/.local/lib/python3.11/site-packages/mlflow/utils/rest_utils.py", line 204, in http_request
[2025-04-11T07:45:35.305+0000] {subprocess.py:106} INFO -     raise MlflowException(f"API request to {url} failed with exception {e}")
[2025-04-11T07:45:35.305+0000] {subprocess.py:106} INFO - mlflow.exceptions.MlflowException: API request to http://localhost:5001/api/2.0/mlflow/experiments/get-by-name failed with exception HTTPConnectionPool(host='localhost', port=5001): Max retries exceeded with url: /api/2.0/mlflow/experiments/get-by-name?experiment_name=Stock_Price_Prediction_LSTM_Refactored (Caused by NewConnectionError('<urllib3.connection.HTTPConnection object at 0x7f1fbe1d8750>: Failed to establish a new connection: [Errno 111] Connection refused'))
[2025-04-11T07:45:36.078+0000] {subprocess.py:110} INFO - Command exited with return code 1
[2025-04-11T07:45:36.094+0000] {taskinstance.py:3313} ERROR - Task failed with exception
Traceback (most recent call last):
  File "/home/airflow/.local/lib/python3.11/site-packages/airflow/models/taskinstance.py", line 768, in _execute_task
    result = _execute_callable(context=context, **execute_callable_kwargs)
             ^^^^^^^^^^^^^^^^^^^^^^^^^^^^^^^^^^^^^^^^^^^^^^^^^^^^^^^^^^^^^
  File "/home/airflow/.local/lib/python3.11/site-packages/airflow/models/taskinstance.py", line 734, in _execute_callable
    return ExecutionCallableRunner(
           ^^^^^^^^^^^^^^^^^^^^^^^^
  File "/home/airflow/.local/lib/python3.11/site-packages/airflow/utils/operator_helpers.py", line 252, in run
    return self.func(*args, **kwargs)
           ^^^^^^^^^^^^^^^^^^^^^^^^^^
  File "/home/airflow/.local/lib/python3.11/site-packages/airflow/models/baseoperator.py", line 424, in wrapper
    return func(self, *args, **kwargs)
           ^^^^^^^^^^^^^^^^^^^^^^^^^^^
  File "/home/airflow/.local/lib/python3.11/site-packages/airflow/operators/bash.py", line 276, in execute
    raise AirflowException(
airflow.exceptions.AirflowException: Bash command failed. The command returned a non-zero exit code 1.
[2025-04-11T07:45:36.100+0000] {taskinstance.py:1226} INFO - Marking task as FAILED. dag_id=lstm_stock_prediction_refactored, task_id=train_final_model, run_id=manual__2025-04-11T07:34:50.523738+00:00, execution_date=20250411T073450, start_date=20250411T074124, end_date=20250411T074536
[2025-04-11T07:45:36.122+0000] {taskinstance.py:341} INFO - ::group::Post task execution logs
[2025-04-11T07:45:36.123+0000] {standard_task_runner.py:124} ERROR - Failed to execute job 25 for task train_final_model (Bash command failed. The command returned a non-zero exit code 1.; 465)
Traceback (most recent call last):
  File "/home/airflow/.local/lib/python3.11/site-packages/airflow/task/task_runner/standard_task_runner.py", line 117, in _start_by_fork
    ret = args.func(args, dag=self.dag)
          ^^^^^^^^^^^^^^^^^^^^^^^^^^^^^
  File "/home/airflow/.local/lib/python3.11/site-packages/airflow/cli/cli_config.py", line 49, in command
    return func(*args, **kwargs)
           ^^^^^^^^^^^^^^^^^^^^^
  File "/home/airflow/.local/lib/python3.11/site-packages/airflow/utils/cli.py", line 116, in wrapper
    return f(*args, **kwargs)
           ^^^^^^^^^^^^^^^^^^
  File "/home/airflow/.local/lib/python3.11/site-packages/airflow/cli/commands/task_command.py", line 483, in task_run
    task_return_code = _run_task_by_selected_method(args, _dag, ti)
                       ^^^^^^^^^^^^^^^^^^^^^^^^^^^^^^^^^^^^^^^^^^^^
  File "/home/airflow/.local/lib/python3.11/site-packages/airflow/cli/commands/task_command.py", line 256, in _run_task_by_selected_method
    return _run_raw_task(args, ti)
           ^^^^^^^^^^^^^^^^^^^^^^^
  File "/home/airflow/.local/lib/python3.11/site-packages/airflow/cli/commands/task_command.py", line 341, in _run_raw_task
    return ti._run_raw_task(
           ^^^^^^^^^^^^^^^^^
  File "/home/airflow/.local/lib/python3.11/site-packages/airflow/utils/session.py", line 97, in wrapper
    return func(*args, session=session, **kwargs)
           ^^^^^^^^^^^^^^^^^^^^^^^^^^^^^^^^^^^^^^
  File "/home/airflow/.local/lib/python3.11/site-packages/airflow/models/taskinstance.py", line 3006, in _run_raw_task
    return _run_raw_task(
           ^^^^^^^^^^^^^^
  File "/home/airflow/.local/lib/python3.11/site-packages/airflow/models/taskinstance.py", line 274, in _run_raw_task
    TaskInstance._execute_task_with_callbacks(
  File "/home/airflow/.local/lib/python3.11/site-packages/airflow/models/taskinstance.py", line 3161, in _execute_task_with_callbacks
    result = self._execute_task(context, task_orig)
             ^^^^^^^^^^^^^^^^^^^^^^^^^^^^^^^^^^^^^^
  File "/home/airflow/.local/lib/python3.11/site-packages/airflow/models/taskinstance.py", line 3185, in _execute_task
    return _execute_task(self, context, task_orig)
           ^^^^^^^^^^^^^^^^^^^^^^^^^^^^^^^^^^^^^^^
  File "/home/airflow/.local/lib/python3.11/site-packages/airflow/models/taskinstance.py", line 768, in _execute_task
    result = _execute_callable(context=context, **execute_callable_kwargs)
             ^^^^^^^^^^^^^^^^^^^^^^^^^^^^^^^^^^^^^^^^^^^^^^^^^^^^^^^^^^^^^
  File "/home/airflow/.local/lib/python3.11/site-packages/airflow/models/taskinstance.py", line 734, in _execute_callable
    return ExecutionCallableRunner(
           ^^^^^^^^^^^^^^^^^^^^^^^^
  File "/home/airflow/.local/lib/python3.11/site-packages/airflow/utils/operator_helpers.py", line 252, in run
    return self.func(*args, **kwargs)
           ^^^^^^^^^^^^^^^^^^^^^^^^^^
  File "/home/airflow/.local/lib/python3.11/site-packages/airflow/models/baseoperator.py", line 424, in wrapper
    return func(self, *args, **kwargs)
           ^^^^^^^^^^^^^^^^^^^^^^^^^^^
  File "/home/airflow/.local/lib/python3.11/site-packages/airflow/operators/bash.py", line 276, in execute
    raise AirflowException(
airflow.exceptions.AirflowException: Bash command failed. The command returned a non-zero exit code 1.
[2025-04-11T07:45:36.142+0000] {local_task_job_runner.py:266} INFO - Task exited with return code 1
[2025-04-11T07:45:36.155+0000] {taskinstance.py:3901} INFO - 0 downstream tasks scheduled from follow-on schedule check
[2025-04-11T07:45:36.166+0000] {local_task_job_runner.py:245} INFO - ::endgroup::
