[2025-04-11T09:03:26.177+0000] {local_task_job_runner.py:123} INFO - ::group::Pre task execution logs
[2025-04-11T09:03:26.194+0000] {taskinstance.py:2614} INFO - Dependencies all met for dep_context=non-requeueable deps ti=<TaskInstance: lstm_stock_prediction_refactored.train_final_model manual__2025-04-11T09:03:07.113573+00:00 [queued]>
[2025-04-11T09:03:26.202+0000] {taskinstance.py:2614} INFO - Dependencies all met for dep_context=requeueable deps ti=<TaskInstance: lstm_stock_prediction_refactored.train_final_model manual__2025-04-11T09:03:07.113573+00:00 [queued]>
[2025-04-11T09:03:26.203+0000] {taskinstance.py:2867} INFO - Starting attempt 1 of 2
[2025-04-11T09:03:26.213+0000] {taskinstance.py:2890} INFO - Executing <Task(BashOperator): train_final_model> on 2025-04-11 09:03:07.113573+00:00
[2025-04-11T09:03:26.218+0000] {standard_task_runner.py:72} INFO - Started process 312 to run task
[2025-04-11T09:03:26.221+0000] {standard_task_runner.py:104} INFO - Running: ['***', 'tasks', 'run', 'lstm_stock_prediction_refactored', 'train_final_model', 'manual__2025-04-11T09:03:07.113573+00:00', '--job-id', '46', '--raw', '--subdir', 'DAGS_FOLDER/lstm_refactored_dag.py', '--cfg-path', '/tmp/tmpgm5rgt2f']
[2025-04-11T09:03:26.223+0000] {standard_task_runner.py:105} INFO - Job 46: Subtask train_final_model
[2025-04-11T09:03:26.279+0000] {task_command.py:467} INFO - Running <TaskInstance: lstm_stock_prediction_refactored.train_final_model manual__2025-04-11T09:03:07.113573+00:00 [running]> on host 8d1fb7443580
[2025-04-11T09:03:26.372+0000] {taskinstance.py:3134} INFO - Exporting env vars: AIRFLOW_CTX_DAG_OWNER='***_team' AIRFLOW_CTX_DAG_ID='lstm_stock_prediction_refactored' AIRFLOW_CTX_TASK_ID='train_final_model' AIRFLOW_CTX_EXECUTION_DATE='2025-04-11T09:03:07.113573+00:00' AIRFLOW_CTX_TRY_NUMBER='1' AIRFLOW_CTX_DAG_RUN_ID='manual__2025-04-11T09:03:07.113573+00:00'
[2025-04-11T09:03:26.374+0000] {taskinstance.py:732} INFO - ::endgroup::
[2025-04-11T09:03:26.389+0000] {subprocess.py:78} INFO - Tmp dir root location: /tmp
[2025-04-11T09:03:26.390+0000] {subprocess.py:88} INFO - Running command: ['/usr/bin/bash', '-c', 'python /opt/***/src/models/train_model.py --config /opt/***/config/params.yaml']
[2025-04-11T09:03:26.403+0000] {subprocess.py:99} INFO - Output:
[2025-04-11T09:07:36.605+0000] {subprocess.py:106} INFO - Using device: cpu
[2025-04-11T09:07:36.607+0000] {subprocess.py:106} INFO - --- Loading Scaled Data from /opt/***/data/features/split_scaled_data.npz ---
[2025-04-11T09:07:36.608+0000] {subprocess.py:106} INFO - --- Finished Loading Scaled Data ---
[2025-04-11T09:07:36.608+0000] {subprocess.py:106} INFO - --- Loading Scalers from /opt/***/data/processed/scalers.pkl ---
[2025-04-11T09:07:36.609+0000] {subprocess.py:106} INFO - --- Finished Loading Scalers ---
[2025-04-11T09:07:36.610+0000] {subprocess.py:106} INFO - --- Loading Tickers from /opt/***/data/processed/all_processed_data.npz ---
[2025-04-11T09:07:36.610+0000] {subprocess.py:106} INFO - Tickers: ['AAPL', 'MA', 'CSCO', 'MSFT', 'AMZN', 'GOOG', 'IBM']
[2025-04-11T09:07:36.611+0000] {subprocess.py:106} INFO - --- Finished Loading Tickers ---
[2025-04-11T09:07:36.611+0000] {subprocess.py:106} INFO - --- Loading Best Hyperparameters from /opt/***/config/best_params.json ---
[2025-04-11T09:07:36.612+0000] {subprocess.py:106} INFO - Best parameters loaded: {'batch_size': 80, 'hidden_size': 96, 'num_layers': 3, 'dropout_rate': 0.2, 'learning_rate': 0.00041228532003489987, 'model_type': 'lstm'}
[2025-04-11T09:07:36.613+0000] {subprocess.py:106} INFO - --- Finished Loading Best Hyperparameters ---
[2025-04-11T09:07:36.614+0000] {subprocess.py:106} INFO - --- Setting MLflow Experiment: Stock_Price_Prediction_LSTM_Refactored ---
[2025-04-11T09:07:36.614+0000] {subprocess.py:106} INFO - Using MLflow Tracking URI: http://localhost:5001/
[2025-04-11T09:07:36.615+0000] {subprocess.py:106} INFO - Traceback (most recent call last):
[2025-04-11T09:07:36.616+0000] {subprocess.py:106} INFO -   File "/home/***/.local/lib/python3.11/site-packages/urllib3/connection.py", line 198, in _new_conn
[2025-04-11T09:07:36.616+0000] {subprocess.py:106} INFO -     sock = connection.create_connection(
[2025-04-11T09:07:36.617+0000] {subprocess.py:106} INFO -            ^^^^^^^^^^^^^^^^^^^^^^^^^^^^^
[2025-04-11T09:07:36.618+0000] {subprocess.py:106} INFO -   File "/home/***/.local/lib/python3.11/site-packages/urllib3/util/connection.py", line 85, in create_connection
[2025-04-11T09:07:36.619+0000] {subprocess.py:106} INFO -     raise err
[2025-04-11T09:07:36.619+0000] {subprocess.py:106} INFO -   File "/home/***/.local/lib/python3.11/site-packages/urllib3/util/connection.py", line 73, in create_connection
[2025-04-11T09:07:36.620+0000] {subprocess.py:106} INFO -     sock.connect(sa)
[2025-04-11T09:07:36.621+0000] {subprocess.py:106} INFO - ConnectionRefusedError: [Errno 111] Connection refused
[2025-04-11T09:07:36.622+0000] {subprocess.py:106} INFO - 
[2025-04-11T09:07:36.623+0000] {subprocess.py:106} INFO - The above exception was the direct cause of the following exception:
[2025-04-11T09:07:36.624+0000] {subprocess.py:106} INFO - 
[2025-04-11T09:07:36.624+0000] {subprocess.py:106} INFO - Traceback (most recent call last):
[2025-04-11T09:07:36.625+0000] {subprocess.py:106} INFO -   File "/home/***/.local/lib/python3.11/site-packages/urllib3/connectionpool.py", line 787, in urlopen
[2025-04-11T09:07:36.625+0000] {subprocess.py:106} INFO -     response = self._make_request(
[2025-04-11T09:07:36.626+0000] {subprocess.py:106} INFO -                ^^^^^^^^^^^^^^^^^^^
[2025-04-11T09:07:36.627+0000] {subprocess.py:106} INFO -   File "/home/***/.local/lib/python3.11/site-packages/urllib3/connectionpool.py", line 493, in _make_request
[2025-04-11T09:07:36.627+0000] {subprocess.py:106} INFO -     conn.request(
[2025-04-11T09:07:36.628+0000] {subprocess.py:106} INFO -   File "/home/***/.local/lib/python3.11/site-packages/urllib3/connection.py", line 445, in request
[2025-04-11T09:07:36.629+0000] {subprocess.py:106} INFO -     self.endheaders()
[2025-04-11T09:07:36.629+0000] {subprocess.py:106} INFO -   File "/usr/local/lib/python3.11/http/client.py", line 1293, in endheaders
[2025-04-11T09:07:36.630+0000] {subprocess.py:106} INFO -     self._send_output(message_body, encode_chunked=encode_chunked)
[2025-04-11T09:07:36.630+0000] {subprocess.py:106} INFO -   File "/usr/local/lib/python3.11/http/client.py", line 1052, in _send_output
[2025-04-11T09:07:36.631+0000] {subprocess.py:106} INFO -     self.send(msg)
[2025-04-11T09:07:36.631+0000] {subprocess.py:106} INFO -   File "/usr/local/lib/python3.11/http/client.py", line 990, in send
[2025-04-11T09:07:36.632+0000] {subprocess.py:106} INFO -     self.connect()
[2025-04-11T09:07:36.633+0000] {subprocess.py:106} INFO -   File "/home/***/.local/lib/python3.11/site-packages/urllib3/connection.py", line 276, in connect
[2025-04-11T09:07:36.633+0000] {subprocess.py:106} INFO -     self.sock = self._new_conn()
[2025-04-11T09:07:36.634+0000] {subprocess.py:106} INFO -                 ^^^^^^^^^^^^^^^^
[2025-04-11T09:07:36.635+0000] {subprocess.py:106} INFO -   File "/home/***/.local/lib/python3.11/site-packages/urllib3/connection.py", line 213, in _new_conn
[2025-04-11T09:07:36.636+0000] {subprocess.py:106} INFO -     raise NewConnectionError(
[2025-04-11T09:07:36.637+0000] {subprocess.py:106} INFO - urllib3.exceptions.NewConnectionError: <urllib3.connection.HTTPConnection object at 0x7febc3980a90>: Failed to establish a new connection: [Errno 111] Connection refused
[2025-04-11T09:07:36.637+0000] {subprocess.py:106} INFO - 
[2025-04-11T09:07:36.638+0000] {subprocess.py:106} INFO - The above exception was the direct cause of the following exception:
[2025-04-11T09:07:36.638+0000] {subprocess.py:106} INFO - 
[2025-04-11T09:07:36.638+0000] {subprocess.py:106} INFO - Traceback (most recent call last):
[2025-04-11T09:07:36.639+0000] {subprocess.py:106} INFO -   File "/home/***/.local/lib/python3.11/site-packages/requests/adapters.py", line 667, in send
[2025-04-11T09:07:36.639+0000] {subprocess.py:106} INFO -     resp = conn.urlopen(
[2025-04-11T09:07:36.640+0000] {subprocess.py:106} INFO -            ^^^^^^^^^^^^^
[2025-04-11T09:07:36.641+0000] {subprocess.py:106} INFO -   File "/home/***/.local/lib/python3.11/site-packages/urllib3/connectionpool.py", line 871, in urlopen
[2025-04-11T09:07:36.642+0000] {subprocess.py:106} INFO -     return self.urlopen(
[2025-04-11T09:07:36.642+0000] {subprocess.py:106} INFO -            ^^^^^^^^^^^^^
[2025-04-11T09:07:36.643+0000] {subprocess.py:106} INFO -   File "/home/***/.local/lib/python3.11/site-packages/urllib3/connectionpool.py", line 871, in urlopen
[2025-04-11T09:07:36.644+0000] {subprocess.py:106} INFO -     return self.urlopen(
[2025-04-11T09:07:36.644+0000] {subprocess.py:106} INFO -            ^^^^^^^^^^^^^
[2025-04-11T09:07:36.645+0000] {subprocess.py:106} INFO -   File "/home/***/.local/lib/python3.11/site-packages/urllib3/connectionpool.py", line 871, in urlopen
[2025-04-11T09:07:36.645+0000] {subprocess.py:106} INFO -     return self.urlopen(
[2025-04-11T09:07:36.646+0000] {subprocess.py:106} INFO -            ^^^^^^^^^^^^^
[2025-04-11T09:07:36.647+0000] {subprocess.py:106} INFO -   [Previous line repeated 4 more times]
[2025-04-11T09:07:36.647+0000] {subprocess.py:106} INFO -   File "/home/***/.local/lib/python3.11/site-packages/urllib3/connectionpool.py", line 841, in urlopen
[2025-04-11T09:07:36.648+0000] {subprocess.py:106} INFO -     retries = retries.increment(
[2025-04-11T09:07:36.649+0000] {subprocess.py:106} INFO -               ^^^^^^^^^^^^^^^^^^
[2025-04-11T09:07:36.649+0000] {subprocess.py:106} INFO -   File "/home/***/.local/lib/python3.11/site-packages/urllib3/util/retry.py", line 519, in increment
[2025-04-11T09:07:36.650+0000] {subprocess.py:106} INFO -     raise MaxRetryError(_pool, url, reason) from reason  # type: ignore[arg-type]
[2025-04-11T09:07:36.652+0000] {subprocess.py:106} INFO -     ^^^^^^^^^^^^^^^^^^^^^^^^^^^^^^^^^^^^^^^^^^^^^^^^^^^
[2025-04-11T09:07:36.653+0000] {subprocess.py:106} INFO - urllib3.exceptions.MaxRetryError: HTTPConnectionPool(host='localhost', port=5001): Max retries exceeded with url: /api/2.0/mlflow/experiments/get-by-name?experiment_name=Stock_Price_Prediction_LSTM_Refactored (Caused by NewConnectionError('<urllib3.connection.HTTPConnection object at 0x7febc3980a90>: Failed to establish a new connection: [Errno 111] Connection refused'))
[2025-04-11T09:07:36.654+0000] {subprocess.py:106} INFO - 
[2025-04-11T09:07:36.655+0000] {subprocess.py:106} INFO - During handling of the above exception, another exception occurred:
[2025-04-11T09:07:36.655+0000] {subprocess.py:106} INFO - 
[2025-04-11T09:07:36.656+0000] {subprocess.py:106} INFO - Traceback (most recent call last):
[2025-04-11T09:07:36.657+0000] {subprocess.py:106} INFO -   File "/home/***/.local/lib/python3.11/site-packages/mlflow/utils/rest_utils.py", line 181, in http_request
[2025-04-11T09:07:36.658+0000] {subprocess.py:106} INFO -     return _get_http_response_with_retries(
[2025-04-11T09:07:36.658+0000] {subprocess.py:106} INFO -            ^^^^^^^^^^^^^^^^^^^^^^^^^^^^^^^^
[2025-04-11T09:07:36.659+0000] {subprocess.py:106} INFO -   File "/home/***/.local/lib/python3.11/site-packages/mlflow/utils/request_utils.py", line 237, in _get_http_response_with_retries
[2025-04-11T09:07:36.660+0000] {subprocess.py:106} INFO -     return session.request(method, url, allow_redirects=allow_redirects, **kwargs)
[2025-04-11T09:07:36.660+0000] {subprocess.py:106} INFO -            ^^^^^^^^^^^^^^^^^^^^^^^^^^^^^^^^^^^^^^^^^^^^^^^^^^^^^^^^^^^^^^^^^^^^^^^
[2025-04-11T09:07:36.661+0000] {subprocess.py:106} INFO -   File "/home/***/.local/lib/python3.11/site-packages/requests/sessions.py", line 589, in request
[2025-04-11T09:07:36.661+0000] {subprocess.py:106} INFO -     resp = self.send(prep, **send_kwargs)
[2025-04-11T09:07:36.662+0000] {subprocess.py:106} INFO -            ^^^^^^^^^^^^^^^^^^^^^^^^^^^^^^
[2025-04-11T09:07:36.663+0000] {subprocess.py:106} INFO -   File "/home/***/.local/lib/python3.11/site-packages/requests/sessions.py", line 703, in send
[2025-04-11T09:07:36.663+0000] {subprocess.py:106} INFO -     r = adapter.send(request, **kwargs)
[2025-04-11T09:07:36.664+0000] {subprocess.py:106} INFO -         ^^^^^^^^^^^^^^^^^^^^^^^^^^^^^^^
[2025-04-11T09:07:36.665+0000] {subprocess.py:106} INFO -   File "/home/***/.local/lib/python3.11/site-packages/requests/adapters.py", line 700, in send
[2025-04-11T09:07:36.665+0000] {subprocess.py:106} INFO -     raise ConnectionError(e, request=request)
[2025-04-11T09:07:36.666+0000] {subprocess.py:106} INFO - requests.exceptions.ConnectionError: HTTPConnectionPool(host='localhost', port=5001): Max retries exceeded with url: /api/2.0/mlflow/experiments/get-by-name?experiment_name=Stock_Price_Prediction_LSTM_Refactored (Caused by NewConnectionError('<urllib3.connection.HTTPConnection object at 0x7febc3980a90>: Failed to establish a new connection: [Errno 111] Connection refused'))
[2025-04-11T09:07:36.668+0000] {subprocess.py:106} INFO - 
[2025-04-11T09:07:36.669+0000] {subprocess.py:106} INFO - During handling of the above exception, another exception occurred:
[2025-04-11T09:07:36.669+0000] {subprocess.py:106} INFO - 
[2025-04-11T09:07:36.670+0000] {subprocess.py:106} INFO - Traceback (most recent call last):
[2025-04-11T09:07:36.671+0000] {subprocess.py:106} INFO -   File "/opt/***/src/models/train_model.py", line 241, in <module>
[2025-04-11T09:07:36.671+0000] {subprocess.py:106} INFO -     run_training(args.config)
[2025-04-11T09:07:36.672+0000] {subprocess.py:106} INFO -   File "/opt/***/src/models/train_model.py", line 215, in run_training
[2025-04-11T09:07:36.673+0000] {subprocess.py:106} INFO -     mlflow.set_experiment(mlflow_experiment)
[2025-04-11T09:07:36.673+0000] {subprocess.py:106} INFO -   File "/home/***/.local/lib/python3.11/site-packages/mlflow/tracking/fluent.py", line 157, in set_experiment
[2025-04-11T09:07:36.674+0000] {subprocess.py:106} INFO -     experiment = client.get_experiment_by_name(experiment_name)
[2025-04-11T09:07:36.674+0000] {subprocess.py:106} INFO -                  ^^^^^^^^^^^^^^^^^^^^^^^^^^^^^^^^^^^^^^^^^^^^^^
[2025-04-11T09:07:36.675+0000] {subprocess.py:106} INFO -   File "/home/***/.local/lib/python3.11/site-packages/mlflow/tracking/client.py", line 1698, in get_experiment_by_name
[2025-04-11T09:07:36.676+0000] {subprocess.py:106} INFO -     return self._tracking_client.get_experiment_by_name(name)
[2025-04-11T09:07:36.676+0000] {subprocess.py:106} INFO -            ^^^^^^^^^^^^^^^^^^^^^^^^^^^^^^^^^^^^^^^^^^^^^^^^^^
[2025-04-11T09:07:36.677+0000] {subprocess.py:106} INFO -   File "/home/***/.local/lib/python3.11/site-packages/mlflow/tracking/_tracking_service/client.py", line 586, in get_experiment_by_name
[2025-04-11T09:07:36.678+0000] {subprocess.py:106} INFO -     return self.store.get_experiment_by_name(name)
[2025-04-11T09:07:36.679+0000] {subprocess.py:106} INFO -            ^^^^^^^^^^^^^^^^^^^^^^^^^^^^^^^^^^^^^^^
[2025-04-11T09:07:36.679+0000] {subprocess.py:106} INFO -   File "/home/***/.local/lib/python3.11/site-packages/mlflow/store/tracking/rest_store.py", line 641, in get_experiment_by_name
[2025-04-11T09:07:36.680+0000] {subprocess.py:106} INFO -     response_proto = self._call_endpoint(GetExperimentByName, req_body)
[2025-04-11T09:07:36.680+0000] {subprocess.py:106} INFO -                      ^^^^^^^^^^^^^^^^^^^^^^^^^^^^^^^^^^^^^^^^^^^^^^^^^^
[2025-04-11T09:07:36.681+0000] {subprocess.py:106} INFO -   File "/home/***/.local/lib/python3.11/site-packages/mlflow/store/tracking/rest_store.py", line 90, in _call_endpoint
[2025-04-11T09:07:36.681+0000] {subprocess.py:106} INFO -     return call_endpoint(self.get_host_creds(), endpoint, method, json_body, response_proto)
[2025-04-11T09:07:36.682+0000] {subprocess.py:106} INFO -            ^^^^^^^^^^^^^^^^^^^^^^^^^^^^^^^^^^^^^^^^^^^^^^^^^^^^^^^^^^^^^^^^^^^^^^^^^^^^^^^^^
[2025-04-11T09:07:36.684+0000] {subprocess.py:106} INFO -   File "/home/***/.local/lib/python3.11/site-packages/mlflow/utils/rest_utils.py", line 387, in call_endpoint
[2025-04-11T09:07:36.685+0000] {subprocess.py:106} INFO -     response = http_request(**call_kwargs)
[2025-04-11T09:07:36.686+0000] {subprocess.py:106} INFO -                ^^^^^^^^^^^^^^^^^^^^^^^^^^^
[2025-04-11T09:07:36.686+0000] {subprocess.py:106} INFO -   File "/home/***/.local/lib/python3.11/site-packages/mlflow/utils/rest_utils.py", line 204, in http_request
[2025-04-11T09:07:36.687+0000] {subprocess.py:106} INFO -     raise MlflowException(f"API request to {url} failed with exception {e}")
[2025-04-11T09:07:36.688+0000] {subprocess.py:106} INFO - mlflow.exceptions.MlflowException: API request to http://localhost:5001/api/2.0/mlflow/experiments/get-by-name failed with exception HTTPConnectionPool(host='localhost', port=5001): Max retries exceeded with url: /api/2.0/mlflow/experiments/get-by-name?experiment_name=Stock_Price_Prediction_LSTM_Refactored (Caused by NewConnectionError('<urllib3.connection.HTTPConnection object at 0x7febc3980a90>: Failed to establish a new connection: [Errno 111] Connection refused'))
[2025-04-11T09:07:37.417+0000] {subprocess.py:110} INFO - Command exited with return code 1
[2025-04-11T09:07:37.427+0000] {taskinstance.py:3313} ERROR - Task failed with exception
Traceback (most recent call last):
  File "/home/airflow/.local/lib/python3.11/site-packages/airflow/models/taskinstance.py", line 768, in _execute_task
    result = _execute_callable(context=context, **execute_callable_kwargs)
             ^^^^^^^^^^^^^^^^^^^^^^^^^^^^^^^^^^^^^^^^^^^^^^^^^^^^^^^^^^^^^
  File "/home/airflow/.local/lib/python3.11/site-packages/airflow/models/taskinstance.py", line 734, in _execute_callable
    return ExecutionCallableRunner(
           ^^^^^^^^^^^^^^^^^^^^^^^^
  File "/home/airflow/.local/lib/python3.11/site-packages/airflow/utils/operator_helpers.py", line 252, in run
    return self.func(*args, **kwargs)
           ^^^^^^^^^^^^^^^^^^^^^^^^^^
  File "/home/airflow/.local/lib/python3.11/site-packages/airflow/models/baseoperator.py", line 424, in wrapper
    return func(self, *args, **kwargs)
           ^^^^^^^^^^^^^^^^^^^^^^^^^^^
  File "/home/airflow/.local/lib/python3.11/site-packages/airflow/operators/bash.py", line 276, in execute
    raise AirflowException(
airflow.exceptions.AirflowException: Bash command failed. The command returned a non-zero exit code 1.
[2025-04-11T09:07:37.437+0000] {taskinstance.py:1226} INFO - Marking task as UP_FOR_RETRY. dag_id=lstm_stock_prediction_refactored, task_id=train_final_model, run_id=manual__2025-04-11T09:03:07.113573+00:00, execution_date=20250411T090307, start_date=20250411T090326, end_date=20250411T090737
[2025-04-11T09:07:37.459+0000] {taskinstance.py:341} INFO - ::group::Post task execution logs
[2025-04-11T09:07:37.460+0000] {standard_task_runner.py:124} ERROR - Failed to execute job 46 for task train_final_model (Bash command failed. The command returned a non-zero exit code 1.; 312)
Traceback (most recent call last):
  File "/home/airflow/.local/lib/python3.11/site-packages/airflow/task/task_runner/standard_task_runner.py", line 117, in _start_by_fork
    ret = args.func(args, dag=self.dag)
          ^^^^^^^^^^^^^^^^^^^^^^^^^^^^^
  File "/home/airflow/.local/lib/python3.11/site-packages/airflow/cli/cli_config.py", line 49, in command
    return func(*args, **kwargs)
           ^^^^^^^^^^^^^^^^^^^^^
  File "/home/airflow/.local/lib/python3.11/site-packages/airflow/utils/cli.py", line 116, in wrapper
    return f(*args, **kwargs)
           ^^^^^^^^^^^^^^^^^^
  File "/home/airflow/.local/lib/python3.11/site-packages/airflow/cli/commands/task_command.py", line 483, in task_run
    task_return_code = _run_task_by_selected_method(args, _dag, ti)
                       ^^^^^^^^^^^^^^^^^^^^^^^^^^^^^^^^^^^^^^^^^^^^
  File "/home/airflow/.local/lib/python3.11/site-packages/airflow/cli/commands/task_command.py", line 256, in _run_task_by_selected_method
    return _run_raw_task(args, ti)
           ^^^^^^^^^^^^^^^^^^^^^^^
  File "/home/airflow/.local/lib/python3.11/site-packages/airflow/cli/commands/task_command.py", line 341, in _run_raw_task
    return ti._run_raw_task(
           ^^^^^^^^^^^^^^^^^
  File "/home/airflow/.local/lib/python3.11/site-packages/airflow/utils/session.py", line 97, in wrapper
    return func(*args, session=session, **kwargs)
           ^^^^^^^^^^^^^^^^^^^^^^^^^^^^^^^^^^^^^^
  File "/home/airflow/.local/lib/python3.11/site-packages/airflow/models/taskinstance.py", line 3006, in _run_raw_task
    return _run_raw_task(
           ^^^^^^^^^^^^^^
  File "/home/airflow/.local/lib/python3.11/site-packages/airflow/models/taskinstance.py", line 274, in _run_raw_task
    TaskInstance._execute_task_with_callbacks(
  File "/home/airflow/.local/lib/python3.11/site-packages/airflow/models/taskinstance.py", line 3161, in _execute_task_with_callbacks
    result = self._execute_task(context, task_orig)
             ^^^^^^^^^^^^^^^^^^^^^^^^^^^^^^^^^^^^^^
  File "/home/airflow/.local/lib/python3.11/site-packages/airflow/models/taskinstance.py", line 3185, in _execute_task
    return _execute_task(self, context, task_orig)
           ^^^^^^^^^^^^^^^^^^^^^^^^^^^^^^^^^^^^^^^
  File "/home/airflow/.local/lib/python3.11/site-packages/airflow/models/taskinstance.py", line 768, in _execute_task
    result = _execute_callable(context=context, **execute_callable_kwargs)
             ^^^^^^^^^^^^^^^^^^^^^^^^^^^^^^^^^^^^^^^^^^^^^^^^^^^^^^^^^^^^^
  File "/home/airflow/.local/lib/python3.11/site-packages/airflow/models/taskinstance.py", line 734, in _execute_callable
    return ExecutionCallableRunner(
           ^^^^^^^^^^^^^^^^^^^^^^^^
  File "/home/airflow/.local/lib/python3.11/site-packages/airflow/utils/operator_helpers.py", line 252, in run
    return self.func(*args, **kwargs)
           ^^^^^^^^^^^^^^^^^^^^^^^^^^
  File "/home/airflow/.local/lib/python3.11/site-packages/airflow/models/baseoperator.py", line 424, in wrapper
    return func(self, *args, **kwargs)
           ^^^^^^^^^^^^^^^^^^^^^^^^^^^
  File "/home/airflow/.local/lib/python3.11/site-packages/airflow/operators/bash.py", line 276, in execute
    raise AirflowException(
airflow.exceptions.AirflowException: Bash command failed. The command returned a non-zero exit code 1.
[2025-04-11T09:07:37.476+0000] {local_task_job_runner.py:266} INFO - Task exited with return code 1
[2025-04-11T09:07:37.492+0000] {taskinstance.py:3901} INFO - 0 downstream tasks scheduled from follow-on schedule check
[2025-04-11T09:07:37.552+0000] {local_task_job_runner.py:245} INFO - ::endgroup::
