[2025-04-22T08:26:10.308+0000] {local_task_job_runner.py:123} INFO - ::group::Pre task execution logs
[2025-04-22T08:26:10.357+0000] {taskinstance.py:2614} INFO - Dependencies all met for dep_context=non-requeueable deps ti=<TaskInstance: lstm_stock_prediction_refactored.train_final_model manual__2025-04-22T08:25:35.628879+00:00 [queued]>
[2025-04-22T08:26:10.372+0000] {taskinstance.py:2614} INFO - Dependencies all met for dep_context=requeueable deps ti=<TaskInstance: lstm_stock_prediction_refactored.train_final_model manual__2025-04-22T08:25:35.628879+00:00 [queued]>
[2025-04-22T08:26:10.373+0000] {taskinstance.py:2867} INFO - Starting attempt 1 of 2
[2025-04-22T08:26:10.394+0000] {taskinstance.py:2890} INFO - Executing <Task(BashOperator): train_final_model> on 2025-04-22 08:25:35.628879+00:00
[2025-04-22T08:26:10.400+0000] {standard_task_runner.py:72} INFO - Started process 611 to run task
[2025-04-22T08:26:10.405+0000] {standard_task_runner.py:104} INFO - Running: ['***', 'tasks', 'run', 'lstm_stock_prediction_refactored', 'train_final_model', 'manual__2025-04-22T08:25:35.628879+00:00', '--job-id', '24', '--raw', '--subdir', 'DAGS_FOLDER/lstm_refactored_dag.py', '--cfg-path', '/tmp/tmpmvp46dno']
[2025-04-22T08:26:10.410+0000] {standard_task_runner.py:105} INFO - Job 24: Subtask train_final_model
[2025-04-22T08:26:10.457+0000] {task_command.py:467} INFO - Running <TaskInstance: lstm_stock_prediction_refactored.train_final_model manual__2025-04-22T08:25:35.628879+00:00 [running]> on host a528bcf7a8c9
[2025-04-22T08:26:10.587+0000] {taskinstance.py:3134} INFO - Exporting env vars: AIRFLOW_CTX_DAG_OWNER='***_team' AIRFLOW_CTX_DAG_ID='lstm_stock_prediction_refactored' AIRFLOW_CTX_TASK_ID='train_final_model' AIRFLOW_CTX_EXECUTION_DATE='2025-04-22T08:25:35.628879+00:00' AIRFLOW_CTX_TRY_NUMBER='1' AIRFLOW_CTX_DAG_RUN_ID='manual__2025-04-22T08:25:35.628879+00:00'
[2025-04-22T08:26:10.589+0000] {taskinstance.py:732} INFO - ::endgroup::
[2025-04-22T08:26:10.648+0000] {subprocess.py:78} INFO - Tmp dir root location: /tmp
[2025-04-22T08:26:10.655+0000] {subprocess.py:88} INFO - Running command: ['/usr/bin/bash', '-c', 'python /opt/***/src/models/train_model.py --config /opt/***/config/params.yaml']
[2025-04-22T08:26:10.677+0000] {subprocess.py:99} INFO - Output:
[2025-04-22T08:26:20.628+0000] {subprocess.py:106} INFO - 2025/04/22 08:26:20 WARNING mlflow.utils.git_utils: Failed to import Git (the Git executable is probably not on your PATH), so Git SHA is not available. Error: Failed to initialize: Bad git executable.
[2025-04-22T08:26:20.629+0000] {subprocess.py:106} INFO - The git executable must be specified in one of the following ways:
[2025-04-22T08:26:20.629+0000] {subprocess.py:106} INFO -     - be included in your $PATH
[2025-04-22T08:26:20.630+0000] {subprocess.py:106} INFO -     - be set via $GIT_PYTHON_GIT_EXECUTABLE
[2025-04-22T08:26:20.631+0000] {subprocess.py:106} INFO -     - explicitly set via git.refresh(<full-path-to-git-executable>)
[2025-04-22T08:26:20.632+0000] {subprocess.py:106} INFO - 
[2025-04-22T08:26:20.632+0000] {subprocess.py:106} INFO - All git commands will error until this is rectified.
[2025-04-22T08:26:20.633+0000] {subprocess.py:106} INFO - 
[2025-04-22T08:26:20.634+0000] {subprocess.py:106} INFO - This initial message can be silenced or aggravated in the future by setting the
[2025-04-22T08:26:20.634+0000] {subprocess.py:106} INFO - $GIT_PYTHON_REFRESH environment variable. Use one of the following values:
[2025-04-22T08:26:20.635+0000] {subprocess.py:106} INFO -     - quiet|q|silence|s|silent|none|n|0: for no message or exception
[2025-04-22T08:26:20.636+0000] {subprocess.py:106} INFO -     - warn|w|warning|log|l|1: for a warning message (logging level CRITICAL, displayed by default)
[2025-04-22T08:26:20.636+0000] {subprocess.py:106} INFO -     - error|e|exception|raise|r|2: for a raised exception
[2025-04-22T08:26:20.637+0000] {subprocess.py:106} INFO - 
[2025-04-22T08:26:20.638+0000] {subprocess.py:106} INFO - Example:
[2025-04-22T08:26:20.638+0000] {subprocess.py:106} INFO -     export GIT_PYTHON_REFRESH=quiet
[2025-04-22T08:26:20.639+0000] {subprocess.py:106} INFO - 
[2025-04-22T08:27:02.754+0000] {subprocess.py:110} INFO - Command exited with return code -9
[2025-04-22T08:27:03.052+0000] {taskinstance.py:3313} ERROR - Task failed with exception
Traceback (most recent call last):
  File "/home/airflow/.local/lib/python3.11/site-packages/airflow/models/taskinstance.py", line 768, in _execute_task
    result = _execute_callable(context=context, **execute_callable_kwargs)
             ^^^^^^^^^^^^^^^^^^^^^^^^^^^^^^^^^^^^^^^^^^^^^^^^^^^^^^^^^^^^^
  File "/home/airflow/.local/lib/python3.11/site-packages/airflow/models/taskinstance.py", line 734, in _execute_callable
    return ExecutionCallableRunner(
           ^^^^^^^^^^^^^^^^^^^^^^^^
  File "/home/airflow/.local/lib/python3.11/site-packages/airflow/utils/operator_helpers.py", line 252, in run
    return self.func(*args, **kwargs)
           ^^^^^^^^^^^^^^^^^^^^^^^^^^
  File "/home/airflow/.local/lib/python3.11/site-packages/airflow/models/baseoperator.py", line 424, in wrapper
    return func(self, *args, **kwargs)
           ^^^^^^^^^^^^^^^^^^^^^^^^^^^
  File "/home/airflow/.local/lib/python3.11/site-packages/airflow/operators/bash.py", line 276, in execute
    raise AirflowException(
airflow.exceptions.AirflowException: Bash command failed. The command returned a non-zero exit code -9.
[2025-04-22T08:27:03.105+0000] {taskinstance.py:1226} INFO - Marking task as UP_FOR_RETRY. dag_id=lstm_stock_prediction_refactored, task_id=train_final_model, run_id=manual__2025-04-22T08:25:35.628879+00:00, execution_date=20250422T082535, start_date=20250422T082610, end_date=20250422T082703
[2025-04-22T08:27:03.201+0000] {job.py:229} INFO - Heartbeat recovered after 32.58 seconds
[2025-04-22T08:27:03.232+0000] {taskinstance.py:341} INFO - ::group::Post task execution logs
[2025-04-22T08:27:03.237+0000] {standard_task_runner.py:124} ERROR - Failed to execute job 24 for task train_final_model (Bash command failed. The command returned a non-zero exit code -9.; 611)
Traceback (most recent call last):
  File "/home/airflow/.local/lib/python3.11/site-packages/airflow/task/task_runner/standard_task_runner.py", line 117, in _start_by_fork
    ret = args.func(args, dag=self.dag)
          ^^^^^^^^^^^^^^^^^^^^^^^^^^^^^
  File "/home/airflow/.local/lib/python3.11/site-packages/airflow/cli/cli_config.py", line 49, in command
    return func(*args, **kwargs)
           ^^^^^^^^^^^^^^^^^^^^^
  File "/home/airflow/.local/lib/python3.11/site-packages/airflow/utils/cli.py", line 116, in wrapper
    return f(*args, **kwargs)
           ^^^^^^^^^^^^^^^^^^
  File "/home/airflow/.local/lib/python3.11/site-packages/airflow/cli/commands/task_command.py", line 483, in task_run
    task_return_code = _run_task_by_selected_method(args, _dag, ti)
                       ^^^^^^^^^^^^^^^^^^^^^^^^^^^^^^^^^^^^^^^^^^^^
  File "/home/airflow/.local/lib/python3.11/site-packages/airflow/cli/commands/task_command.py", line 256, in _run_task_by_selected_method
    return _run_raw_task(args, ti)
           ^^^^^^^^^^^^^^^^^^^^^^^
  File "/home/airflow/.local/lib/python3.11/site-packages/airflow/cli/commands/task_command.py", line 341, in _run_raw_task
    return ti._run_raw_task(
           ^^^^^^^^^^^^^^^^^
  File "/home/airflow/.local/lib/python3.11/site-packages/airflow/utils/session.py", line 97, in wrapper
    return func(*args, session=session, **kwargs)
           ^^^^^^^^^^^^^^^^^^^^^^^^^^^^^^^^^^^^^^
  File "/home/airflow/.local/lib/python3.11/site-packages/airflow/models/taskinstance.py", line 3006, in _run_raw_task
    return _run_raw_task(
           ^^^^^^^^^^^^^^
  File "/home/airflow/.local/lib/python3.11/site-packages/airflow/models/taskinstance.py", line 274, in _run_raw_task
    TaskInstance._execute_task_with_callbacks(
  File "/home/airflow/.local/lib/python3.11/site-packages/airflow/models/taskinstance.py", line 3161, in _execute_task_with_callbacks
    result = self._execute_task(context, task_orig)
             ^^^^^^^^^^^^^^^^^^^^^^^^^^^^^^^^^^^^^^
  File "/home/airflow/.local/lib/python3.11/site-packages/airflow/models/taskinstance.py", line 3185, in _execute_task
    return _execute_task(self, context, task_orig)
           ^^^^^^^^^^^^^^^^^^^^^^^^^^^^^^^^^^^^^^^
  File "/home/airflow/.local/lib/python3.11/site-packages/airflow/models/taskinstance.py", line 768, in _execute_task
    result = _execute_callable(context=context, **execute_callable_kwargs)
             ^^^^^^^^^^^^^^^^^^^^^^^^^^^^^^^^^^^^^^^^^^^^^^^^^^^^^^^^^^^^^
  File "/home/airflow/.local/lib/python3.11/site-packages/airflow/models/taskinstance.py", line 734, in _execute_callable
    return ExecutionCallableRunner(
           ^^^^^^^^^^^^^^^^^^^^^^^^
  File "/home/airflow/.local/lib/python3.11/site-packages/airflow/utils/operator_helpers.py", line 252, in run
    return self.func(*args, **kwargs)
           ^^^^^^^^^^^^^^^^^^^^^^^^^^
  File "/home/airflow/.local/lib/python3.11/site-packages/airflow/models/baseoperator.py", line 424, in wrapper
    return func(self, *args, **kwargs)
           ^^^^^^^^^^^^^^^^^^^^^^^^^^^
  File "/home/airflow/.local/lib/python3.11/site-packages/airflow/operators/bash.py", line 276, in execute
    raise AirflowException(
airflow.exceptions.AirflowException: Bash command failed. The command returned a non-zero exit code -9.
[2025-04-22T08:27:03.284+0000] {local_task_job_runner.py:266} INFO - Task exited with return code 1
[2025-04-22T08:27:03.342+0000] {taskinstance.py:3901} INFO - 0 downstream tasks scheduled from follow-on schedule check
[2025-04-22T08:27:03.345+0000] {local_task_job_runner.py:245} INFO - ::endgroup::
